<sdf version='1.6'>
  <model name='psm'>
    <link name='base_link'>
      <pose frame=''>0 0 0 0 -0 0</pose>
      <inertial>
        <pose frame=''>-0 -0.17016 -0.085607 0 -0 0</pose>
        <mass>2.0161</mass>
        <inertia>
          <ixx>0.03342853</ixx>
          <ixy>0.00942520</ixy>
          <ixz>-0.00334012</ixz>
          <iyy>0</iyy>
          <iyz>0</iyz>
          <izz>0.02897334</izz>
        </inertia>
      </inertial>
      <collision name='base_link_collision'>
        <pose frame=''>0 0 0 0 -0 0</pose>
        <geometry>
          <mesh>
            <scale>1 1 1</scale>
            <uri>model://psm/meshes/base_link.STL</uri>
          </mesh>
        </geometry>
      </collision>
      <visual name='base_link_visual'>
        <pose frame=''>0 0 0 0 -0 0</pose>
        <geometry>
          <mesh>
            <scale>1 1 1</scale>
            <uri>model://psm/meshes/base_link.STL</uri>
          </mesh>
        </geometry>
        <material>
          <ambient>0.6 0.6 0.6 1</ambient>
          <diffuse>0.6 0.6 0.6 1</diffuse>
          <specular>0.1 0.1 0.1 1</specular>
          <emissive>0 0 0 1</emissive>
        </material>
      </visual>
    </link>
    <link name='yaw_link'>
      <pose frame=''>0 0 0 -1.57079 -1.57079 3.14159</pose>
      <inertial>
        <pose frame=''>-0.038769 7.8e-05 0.041596 0 -0 0</pose>
        <mass>1.4705</mass>
        <inertia>
          <ixx>0.01814321</ixx>
          <ixy>0.0000043</ixy>
          <ixz>0.00000728</ixz>
          <iyy>0.0157145</iyy>
          <iyz>-0.00048589</iyz>
          <izz>0.00824930</izz>
        </inertia>
      </inertial>
      <collision name='yaw_link_collision'>
        <pose frame=''>0 0 0 0 -0 0</pose>
        <geometry>
          <mesh>
            <scale>1 1 1</scale>
            <uri>model://psm/meshes/yaw_link.STL</uri>
          </mesh>
        </geometry>
      </collision>
      <visual name='yaw_link_visual'>
        <pose frame=''>0 0 0 0 -0 0</pose>
        <geometry>
          <mesh>
            <scale>1 1 1</scale>
            <uri>model://psm/meshes/yaw_link.STL</uri>
          </mesh>
        </geometry>
        <material>
          <ambient>0.6 0.6 0.6 1</ambient>
          <diffuse>0.6 0.6 0.6 1</diffuse>
          <specular>0.1 0.1 0.1 1</specular>
          <emissive>0 0 0 1</emissive>
        </material>
      </visual>
    </link>
    <joint name='yaw_joint' type='revolute'>
      <child>yaw_link</child>
      <parent>base_link</parent>
      <axis>
        <xyz>-4e-06 1 -0</xyz>
        <limit>
          <lower>-1.605</lower>
          <upper>1.5994</upper>
          <effort>1000</effort>
          <velocity>10</velocity>
        </limit>
        <dynamics>
          <spring_reference>0</spring_reference>
          <spring_stiffness>0</spring_stiffness>
        </dynamics>
        <use_parent_model_frame>1</use_parent_model_frame>
      </axis>
    </joint>
    <link name='pitch_back_link'>
      <pose frame=''>0 -0.0296 0 1.57081 -1.28007 -1.5708</pose>
      <inertial>
        <pose frame=''>-0.011651 -0.036241 3.6e-05 0 -0 0</pose>
        <!--mass>0.98494</mass-->
        <mass>0.7</mass>
        <inertia>
          <ixx>0.00202417</ixx>
          <ixy>0.00047511</ixy>
          <ixz>0.00000043</ixz>
          <iyy>0.00564963</iyy>
          <iyz>0.00000129</iyz>
          <izz>0.00564716</izz>
        </inertia>
      </inertial>
      <collision name='pitch_back_link_collision'>
        <pose frame=''>0 0 0 0 -0 0</pose>
        <geometry>
          <mesh>
            <scale>1 1 1</scale>
            <uri>model://psm/meshes/pitch_back_link.STL</uri>
          </mesh>
        </geometry>
      </collision>
      <visual name='pitch_back_link_visual'>
        <pose frame=''>0 0 0 0 -0 0</pose>
        <geometry>
          <mesh>
            <scale>1 1 1</scale>
            <uri>model://psm/meshes/pitch_back_link.STL</uri>
          </mesh>
        </geometry>
        <material>
          <ambient>0 0 0 1</ambient>
          <diffuse>0 0 0 1</diffuse>
          <specular>0.8 0.8 0.8 1</specular>
          <emissive>0 0 0 1</emissive>
        </material>
      </visual>
    </link>
    <joint name='pitch_back_joint' type='revolute'>
      <child>pitch_back_link</child>
      <parent>yaw_link</parent>
      <axis>
        <xyz>-1 -0 -3e-06</xyz>
        <limit>
          <lower>-0.93556</lower>
          <upper>0.94249</upper>
          <effort>1000</effort>
          <velocity>10</velocity>
        </limit>
        <dynamics>
          <spring_reference>0</spring_reference>
          <spring_stiffness>0</spring_stiffness>
        </dynamics>
        <use_parent_model_frame>1</use_parent_model_frame>
      </axis>
    </joint>
    <link name='pitch_bottom_link'>
      <pose frame=''>-0 -0.072598 0.143705 -1.5708 -2.6e-05 1.5708</pose>
      <inertial>
        <pose frame=''>0.25683 -0.010348 -6e-06 0 -0 0</pose>
        <mass>0.44569</mass>
        <inertia>
          <ixx>0.00045979</ixx>
          <ixy>-0.00031801</ixy>
          <ixz>0.00000003</ixz>
          <iyy>0.01127103</iyy>
          <iyz>-0.00000040</iyz>
          <izz>0.01110239</izz>
        </inertia>
      </inertial>
      <collision name='pitch_bottom_link_collision'>
        <pose frame=''>0 0 0 0 -0 0</pose>
        <geometry>
          <mesh>
            <scale>1 1 1</scale>
            <uri>model://psm/meshes/pitch_bottom_link.STL</uri>
          </mesh>
        </geometry>
      </collision>
      <visual name='pitch_bottom_link_visual'>
        <pose frame=''>0 0 0 0 -0 0</pose>
        <geometry>
          <mesh>
            <scale>1 1 1</scale>
            <uri>model://psm/meshes/pitch_bottom_link.STL</uri>
          </mesh>
        </geometry>
        <material>
          <ambient>0 0 0 1</ambient>
          <diffuse>0 0 0 1</diffuse>
          <specular>0.8 0.8 0.8 1</specular>
          <emissive>0 0 0 1</emissive>
        </material>
      </visual>
    </link>
    <joint name='pitch_bottom_joint' type='revolute'>
      <child>pitch_bottom_link</child>
      <parent>pitch_back_link</parent>
      <axis>
        <xyz>-1 -0 -3e-06</xyz>
        <limit>
          <lower>-0.94249</lower>
          <upper>0.93556</upper>
          <effort>1000</effort>
          <velocity>10</velocity>
        </limit>
        <dynamics>
          <spring_reference>0</spring_reference>
          <spring_stiffness>0</spring_stiffness>
        </dynamics>
        <use_parent_model_frame>1</use_parent_model_frame>
      </axis>
    </joint>
    <link name='pitch_end_link'>
      <pose frame=''>-0 0.443402 0.143719 -1.5708 -2.6e-05 1.5708</pose>
      <inertial>
        <pose frame=''>-0.001929 -0.13613 -0 0 -0 0</pose>
        <!--mass>2.091</mass-->
        <mass>0.355</mass>
        <inertia>
          <ixx>0.03784466</ixx>
          <ixy>-0.00123970</ixy>
          <ixz>0.00000002</ixz>
          <iyy>0.00156905</iyy>
          <iyz>0</iyz>
          <izz>0.03227453</izz>
        </inertia>
      </inertial>
      <collision name='pitch_end_link_collision'>
        <pose frame=''>0 0 0 0 -0 0</pose>
        <geometry>
          <mesh>
            <scale>1 1 1</scale>
            <uri>model://psm/meshes/pitch_end_link.STL</uri>
          </mesh>
        </geometry>
      </collision>
      <visual name='pitch_end_link_visual'>
        <pose frame=''>0 0 0 0 -0 0</pose>
        <geometry>
          <mesh>
            <scale>1 1 1</scale>
            <uri>model://psm/meshes/pitch_end_link.STL</uri>
          </mesh>
        </geometry>
        <material>
          <ambient>0 0 0 1</ambient>
          <diffuse>0 0 0 1</diffuse>
          <specular>0.8 0.8 0.8 1</specular>
          <emissive>0 0 0 1</emissive>
        </material>
      </visual>
    </link>
    <joint name='pitch_end_joint' type='revolute'>
      <child>pitch_end_link</child>
      <parent>pitch_bottom_link</parent>
      <axis>
        <xyz>-1 -0 -3e-06</xyz>
        <limit>
          <lower>-0.93556</lower>
          <upper>0.94249</upper>
          <effort>1000</effort>
          <velocity>10</velocity>
        </limit>
        <dynamics>
          <spring_reference>0</spring_reference>
          <spring_stiffness>0</spring_stiffness>
        </dynamics>
        <use_parent_model_frame>1</use_parent_model_frame>
      </axis>
    </joint>
    <link name='main_insertion_link'>
      <pose frame=''>-1e-06 0.486395 0.43181 -3.14159 1.9e-05 -1.5708</pose>
      <inertial>
        <pose frame=''>0.004056 -0.000109 0.009862 0 -0 0</pose>
        <mass>0.22491</mass>
        <inertia>
          <!--ixx>1.6985e-05</ixx>
          <ixy>-6.2173e-08</ixy>
          <ixz>1.2317e-05</ixz>
          <iyy>2.5916e-05</iyy>
          <iyz>8.5735e-08</iyz>
          <izz>8.9322e-06</izz-->

          <ixx>0.01</ixx>
          <ixy>-0.00001</ixy>
          <ixz>0.00001</ixz>
          <iyy>0.001</iyy>
          <iyz>0.00001</iyz>
          <izz>0.001</izz>
        </inertia>
      </inertial>
      <collision name='main_insertion_link_collision'>
        <pose frame=''>0 0 0 0 -0 0</pose>
        <geometry>
          <mesh>
            <scale>1 1 1</scale>
            <uri>model://psm/meshes/main_insertion_link.STL</uri>
          </mesh>
        </geometry>
      </collision>
      <visual name='main_insertion_link_visual'>
        <pose frame=''>0 0 0 0 -0 0</pose>
        <geometry>
          <mesh>
            <scale>1 1 1</scale>
            <uri>model://psm/meshes/main_insertion_link.STL</uri>
          </mesh>
        </geometry>
        <material>
          <ambient>0 0 0 1</ambient>
          <diffuse>0 0 0 1</diffuse>
          <specular>0.8 0.8 0.8 1</specular>
          <emissive>0 0 0 1</emissive>
        </material>
      </visual>
    </link>
    <joint name='main_insertion_joint' type='prismatic'>
      <child>main_insertion_link</child>
      <parent>pitch_end_link</parent>
      <axis>
        <xyz>-6e-06 -1.9e-05 -1</xyz>
        <limit>
          <lower>0</lower>
          <upper>0.24</upper>
          <effort>1000</effort>
          <velocity>1</velocity>
        </limit>
        <dynamics>
          <spring_reference>0</spring_reference>
          <spring_stiffness>0</spring_stiffness>
        </dynamics>
        <use_parent_model_frame>1</use_parent_model_frame>
      </axis>
    </joint>
    <link name='tool_roll_link'>
      <pose frame=''>2e-06 0.486403 0.01561 3.14159 -1.9e-05 1.57079</pose>
      <inertial>
        <pose frame=''>-0 -0 -0.005823 0 -0 0</pose>
        <!--mass>0.00033225</mass-->
        <mass>0.012491</mass>
        <inertia>
          <ixx>0.001</ixx>
          <ixy>0.00001</ixy>
          <ixz>0.00001</ixz>
          <iyy>0.001</iyy>
          <iyz>0.00001</iyz>
          <izz>0.001</izz>
        </inertia>
      </inertial>
      <collision name='tool_roll_link_collision'>
        <pose frame=''>0 0 0 0 -0 0</pose>
        <geometry>
          <mesh>
            <scale>1 1 1</scale>
            <uri>model://psm/meshes/tool_roll_link.STL</uri>
          </mesh>
        </geometry>
      </collision>
      <visual name='tool_roll_link_visual'>
        <pose frame=''>0 0 0 0 -0 0</pose>
        <geometry>
          <mesh>
            <scale>1 1 1</scale>
            <uri>model://psm/meshes/tool_roll_link.STL</uri>
          </mesh>
        </geometry>
        <material>
          <ambient>0.8 0.8 0.8 1</ambient>
          <diffuse>0.8 0.8 0.8 1</diffuse>
          <specular>1 1 1 1</specular>
          <emissive>0 0 0 1</emissive>
        </material>
      </visual>
    </link>
    <joint name='tool_roll_joint' type='revolute'>
      <child>tool_roll_link</child>
      <parent>main_insertion_link</parent>
      <axis>
        <xyz>-6e-06 -1.9e-05 -1</xyz>
        <limit>
          <lower>-3.14159</lower>
          <upper>3.14159</upper>
          <effort>1000</effort>
          <velocity>10</velocity>
        </limit>
        <dynamics>
          <spring_reference>0</spring_reference>
          <spring_stiffness>0</spring_stiffness>
        </dynamics>
        <use_parent_model_frame>1</use_parent_model_frame>
      </axis>
    </joint>
    <link name='tool_pitch_link'>
      <pose frame=''>2e-06 0.486403 0.01561 -1.96086 1.57078 1.18072</pose>
      <inertial>
        <pose frame=''>0.003576 -0 4e-06 0 -0 0</pose>
        <!--mass>0.025784</mass-->
        <mass>0.012491</mass>
        <inertia>
          <!--ixx>1.2364e-13</ixx>
          <ixy>2.9238e-15</ixy>
          <ixz>4.1903e-12</ixz>
          <iyy>1.4213e-10</iyy>
          <iyz>-8.6271e-17</iyz>
          <izz>1.4201e-10</izz-->

          <ixx>0.001</ixx>
          <ixy>0.00001</ixy>
          <ixz>0.00001</ixz>
          <iyy>0.001</iyy>
          <iyz>0.00001</iyz>
          <izz>0.001</izz>
        </inertia>
      </inertial>
      <collision name='tool_pitch_link_collision'>
        <pose frame=''>0 0 0 0 -0 0</pose>
        <geometry>
          <mesh>
            <scale>1 1 1</scale>
            <uri>model://psm/meshes/tool_pitch_link.STL</uri>
          </mesh>
        </geometry>
      </collision>
      <visual name='tool_pitch_link_visual'>
        <pose frame=''>0 0 0 0 -0 0</pose>
        <geometry>
          <mesh>
            <scale>1 1 1</scale>
            <uri>model://psm/meshes/tool_pitch_link.STL</uri>
          </mesh>
        </geometry>
        <material>
          <ambient>0.8 0.8 0.8 1</ambient>
          <diffuse>0.8 0.8 0.8 1</diffuse>
          <specular>1 1 1 1</specular>
          <emissive>0 0 0 1</emissive>
        </material>
      </visual>
    </link>
    <joint name='tool_pitch_joint' type='revolute'>
      <child>tool_pitch_link</child>
      <parent>tool_roll_link</parent>
      <axis>
        <xyz>1 -1.1e-05 6e-06</xyz>
        <limit>
          <lower>-1.5708</lower>
          <upper>1.5708</upper>
          <effort>1000</effort>
          <velocity>10</velocity>
        </limit>
        <dynamics>
          <spring_reference>0</spring_reference>
          <spring_stiffness>0</spring_stiffness>
        </dynamics>
        <use_parent_model_frame>1</use_parent_model_frame>
      </axis>
    </joint>
    <link name='tool_yaw_link'>
      <pose frame=''>2e-06 0.486403 0.00651 1.57078 3e-06 3.14158</pose>
      <inertial>
        <pose frame=''>-0 -0 -5e-05 0 -0 0</pose>
        <!--mass>6.6366e-06</mass-->
        <!--mass>0.025784</mass-->
        <mass>0.012491</mass>
        <inertia>
          <ixx>0.001</ixx>
          <ixy>0.00001</ixy>
          <ixz>0.00001</ixz>
          <iyy>0.001</iyy>
          <iyz>0.00001</iyz>
          <izz>0.001</izz>
        </inertia>
      </inertial>
      <collision name='tool_yaw_link_collision'>
        <pose frame=''>0 0 0 0 -0 0</pose>
        <geometry>
          <mesh>
            <scale>1 1 1</scale>
            <uri>model://psm/meshes/tool_yaw_link.STL</uri>
          </mesh>
        </geometry>
      </collision>
      <visual name='tool_yaw_link_visual'>
        <pose frame=''>0 0 0 0 -0 0</pose>
        <geometry>
          <mesh>
            <scale>1 1 1</scale>
            <uri>model://psm/meshes/tool_yaw_link.STL</uri>
          </mesh>
        </geometry>
        <material>
          <ambient>0.8 0.8 0.8 1</ambient>
          <diffuse>0.8 0.8 0.8 1</diffuse>
          <specular>1 1 1 1</specular>
          <emissive>0 0 0 1</emissive>
        </material>
      </visual>
    </link>
    <joint name='tool_yaw_joint' type='revolute'>
      <child>tool_yaw_link</child>
      <parent>tool_pitch_link</parent>
      <axis>
        <xyz>1.1e-05 1 1.2e-05</xyz>
        <limit>
          <lower>-1.5708</lower>
          <upper>1.5708</upper>
          <effort>1000</effort>
          <velocity>10</velocity>
        </limit>
        <dynamics>
          <spring_reference>0</spring_reference>
          <spring_stiffness>0</spring_stiffness>
        </dynamics>
        <use_parent_model_frame>1</use_parent_model_frame>
      </axis>
    </joint>

    <link name='tool_gripper1_link'>
      <!--pose frame=''>2e-06 0.486403 0.00651 1.57078 3e-06 3.14158</pose-->
      <pose frame=''>2e-06 0.486403 0.00651 1.57078 3.14158 3.14158</pose>
      <inertial>
        <pose frame=''>0.000196 0.001435 -0.000885 0 -0 0</pose>
        <!--mass>3.7467e-05</mass-->
        <mass>0.010491</mass>

        <inertia>
          <ixx>0.001</ixx>
          <ixy>0.00001</ixy>
          <ixz>0.00001</ixz>
          <iyy>0.001</iyy>
          <iyz>0.00001</iyz>
          <izz>0.001</izz>
        </inertia>
      </inertial>
      <collision name='tool_gripper1_link_collision'>
        <pose frame=''>0 0 0 0 -0 0</pose>
        <geometry>
          <mesh>
            <scale>1 1 1</scale>
            <uri>model://psm/meshes/tool_gripper1_link.STL</uri>
          </mesh>
        </geometry>
      </collision>
      <visual name='tool_gripper1_link_visual'>
        <pose frame=''>0 0 0 0 -0 0</pose>
        <geometry>
          <mesh>
            <scale>1 1 1</scale>
            <uri>model://psm/meshes/tool_gripper1_link.STL</uri>
          </mesh>
        </geometry>
        <material>
          <ambient>0.8 0.8 0.8 1</ambient>
          <diffuse>0.8 0.8 0.8 1</diffuse>
          <specular>1 1 1 1</specular>
          <emissive>0 0 0 1</emissive>
        </material>
      </visual>
    </link>
    <joint name='tool_gripper1_joint' type='revolute'>
      <child>tool_gripper1_link</child>
      <parent>tool_yaw_link</parent>
      <axis>
        <xyz>1.1e-05 -1 1.2e-05</xyz>
        <limit>
          <lower>0</lower>
          <upper>1</upper>
          <effort>0</effort>
          <velocity>0</velocity>
        </limit>
        <dynamics>
          <spring_reference>0</spring_reference>
          <spring_stiffness>0</spring_stiffness>
        </dynamics>
        <use_parent_model_frame>1</use_parent_model_frame>
      </axis>
    </joint>
    <link name='tool_gripper2_link'>
      <!--pose frame=''>2e-06 0.486403 0.00651 1.57078 3e-06 3.14158</pose-->
      <pose frame=''>2e-06 0.486403 0.00651 1.57078 3.14158 3.14158</pose>
      <inertial>
        <pose frame=''>-0.000196 0.001435 0.000885 0 -0 0</pose>
        <!--mass>3.7467e-05</mass-->
        <mass>0.010491</mass>
        <inertia>
          <ixx>0.001</ixx>
          <ixy>0.00001</ixy>
          <ixz>0.00001</ixz>
          <iyy>0.001</iyy>
          <iyz>0.00001</iyz>
          <izz>0.001</izz>
        </inertia>
      </inertial>
      <collision name='tool_gripper2_link_collision'>
        <pose frame=''>0 0 0 0 -0 0</pose>
        <geometry>
          <mesh>
            <scale>1 1 1</scale>
            <uri>model://psm/meshes/tool_gripper2_link.STL</uri>
          </mesh>
        </geometry>
      </collision>
      <visual name='tool_gripper2_link_visual'>
        <pose frame=''>0 0 0 0 -0 0</pose>
        <geometry>
          <mesh>
            <scale>1 1 1</scale>
            <uri>model://psm/meshes/tool_gripper2_link.STL</uri>
          </mesh>
        </geometry>
        <material>
          <ambient>0.8 0.8 0.8 1</ambient>
          <diffuse>0.8 0.8 0.8 1</diffuse>
          <specular>1 1 1 1</specular>
          <emissive>0 0 0 1</emissive>
        </material>
      </visual>
    </link>
    <joint name='tool_gripper2_joint' type='revolute'>
      <child>tool_gripper2_link</child>
      <parent>tool_yaw_link</parent>
      <axis>
        <xyz>1.1e-05 1 1.2e-05</xyz>
        <limit>
          <lower>0</lower>
          <upper>1</upper>
          <effort>0</effort>
          <velocity>0</velocity>
        </limit>
        <dynamics>
          <spring_reference>0</spring_reference>
          <spring_stiffness>0</spring_stiffness>
        </dynamics>
        <use_parent_model_frame>1</use_parent_model_frame>
      </axis>
    </joint>
    <link name='pitch_top_link'>
      <pose frame=''>-0 -0.068718 0.18 -1.5708 -2.6e-05 1.5708</pose>
      <inertial>
        <pose frame=''>0.31246 -0.000566 -0 0 -0 0</pose>
        <mass>0.17841</mass>
        <inertia>
          <ixx>0.00014989</ixx>
          <ixy>0.00001128</ixy>
          <ixz>0</ixz>
          <iyy>0.00463460</iyy>
          <iyz>0</iyz>
          <izz>0.00449516</izz>
        </inertia>
      </inertial>
      <collision name='pitch_top_link_collision'>
        <pose frame=''>0 0 0 0 -0 0</pose>
        <geometry>
          <mesh>
            <scale>1 1 1</scale>
            <uri>model://psm/meshes/pitch_top_link.STL</uri>
          </mesh>
        </geometry>
      </collision>
      <visual name='pitch_top_link_visual'>
        <pose frame=''>0 0 0 0 -0 0</pose>
        <geometry>
          <mesh>
            <scale>1 1 1</scale>
            <uri>model://psm/meshes/pitch_top_link.STL</uri>
          </mesh>
        </geometry>
        <material>
          <ambient>0 0 0 1</ambient>
          <diffuse>0 0 0 1</diffuse>
          <specular>0.8 0.8 0.8 1</specular>
          <emissive>0 0 0 1</emissive>
        </material>
      </visual>
    </link>
    <joint name='pitch_top_joint' type='revolute'>
      <child>pitch_top_link</child>
      <parent>pitch_back_link</parent>
      <axis>
        <xyz>-1 -0 -3e-06</xyz>
        <limit>
          <lower>-0.94249</lower>
          <upper>0.93556</upper>
          <effort>1000</effort>
          <velocity>10</velocity>
        </limit>
        <dynamics>
          <spring_reference>0</spring_reference>
          <spring_stiffness>0</spring_stiffness>
        </dynamics>
        <use_parent_model_frame>1</use_parent_model_frame>
      </axis>
    </joint>
    <link name='pitch_front_link'>
      <pose frame=''>-0 0.0664 -0 1.57081 -1.28007 -1.5708</pose>
      <inertial>
        <pose frame=''>0.096269 0 0.047551 0 -0 0</pose>
        <mass>0.074425</mass>
        <inertia>
          <ixx>0.00000876</ixx>
          <ixy>0</ixy>
          <ixz>-0.00001711</ixz>
          <iyy>0.00022654</iyy>
          <iyz>0</iyz>
          <izz>00.00022322</izz>
        </inertia>
      </inertial>
      <collision name='pitch_front_link_collision'>
        <pose frame=''>0 0 0 0 -0 0</pose>
        <geometry>
          <mesh>
            <scale>1 1 1</scale>
            <uri>model://psm/meshes/pitch_front_link.STL</uri>
          </mesh>
        </geometry>
      </collision>
      <visual name='pitch_front_link_visual'>
        <pose frame=''>0 0 0 0 -0 0</pose>
        <geometry>
          <mesh>
            <scale>1 1 1</scale>
            <uri>model://psm/meshes/pitch_front_link.STL</uri>
          </mesh>
        </geometry>
        <material>
          <ambient>0 0 0 1</ambient>
          <diffuse>0 0 0 1</diffuse>
          <specular>0.8 0.8 0.8 1</specular>
          <emissive>0 0 0 1</emissive>
        </material>
      </visual>
    </link>
    <joint name='pitch_front_joint' type='revolute'>
      <child>pitch_front_link</child>
      <parent>yaw_link</parent>
      <axis>
        <xyz>-1 -0 -3e-06</xyz>
        <limit>
          <lower>-0.93556</lower>
          <upper>0.94249</upper>
          <effort>1000</effort>
          <velocity>10</velocity>
        </limit>
        <dynamics>
          <spring_reference>0</spring_reference>
          <spring_stiffness>0</spring_stiffness>
        </dynamics>
        <use_parent_model_frame>1</use_parent_model_frame>
      </axis>
    </joint>

    <joint name='pitch_front_bottom_joint' type='revolute'>
      <pose>0.096 0 0 0 0 0 </pose>
      <child>pitch_bottom_link</child>
      <parent>pitch_front_link</parent>
      <axis>
        <xyz>-1 0 0</xyz>
        <limit>
          <lower>-0.93556</lower>
          <upper>0.94249</upper>
          <effort>1000</effort>
          <velocity>1</velocity>
        </limit>
        <dynamics>
          <spring_reference>0</spring_reference>
          <spring_stiffness>0</spring_stiffness>
        </dynamics>
        <use_parent_model_frame>1</use_parent_model_frame>
      </axis>
    </joint>

    <joint name='pitch_top_end_joint' type='revolute'>
      <pose>0.00388 -0.036293189  0 0 0 0 </pose>
      <child>pitch_end_link</child>
      <parent>pitch_top_link</parent>
      <axis>
        <xyz>-1 0 0</xyz>
        <limit>
          <lower>-0.93556</lower>
          <upper>0.94249</upper>
          <effort>1000</effort>
          <velocity>1</velocity>
        </limit>
        <dynamics>
          <spring_reference>0</spring_reference>
          <spring_stiffness>0</spring_stiffness>
        </dynamics>
        <use_parent_model_frame>1</use_parent_model_frame>
      </axis>
    </joint>
  </model>
</sdf>
