<robot
  name="LaprotekMaster">
  <link name="world"/>
  <joint name="fixed_joint" type="fixed">
  <origin xyz="0 0 0" rpy="0 0 0" />
  <parent link="world"/>
  <child link="base_link"/>
  </joint>

  <link
    name="base_link">
    <inertial>
      <origin
        xyz="-0.057778883152153 0.0166712269416334 0.100861621768359"
        rpy="0 0 0" />
      <mass
        value="60.9463781336671" />
      <inertia
        ixx="18.4694268208303"
        ixy="0.142152811856605"
        ixz="-0.266498923250811"
        iyy="6.65504970202301"
        iyz="0.274053088509721"
        izz="17.1403058490438" />
    </inertial>
    <visual>
      <origin
        xyz="0 0 0"
        rpy="0 0 0" />
      <geometry>
        <mesh
          filename="package://dvrk_model/LaprotekMaster/meshes/base_link.STL" />
      </geometry>
      <material
        name="">
        <color
          rgba="0.792156862745098 0.819607843137255 0.933333333333333 1" />
      </material>
    </visual>
    <collision>
      <origin
        xyz="0 0 0"
        rpy="0 0 0" />
      <geometry>
        <mesh
          filename="package://dvrk_model/LaprotekMaster/meshes/base_link.STL" />
      </geometry>
    </collision>
  </link>
  <link
    name="left_shoulder_link">
    <inertial>
      <origin
        xyz="0 0.0397615591942102 0.00732049360916574"
        rpy="0 0 0" />
      <mass
        value="1.34463372754833" />
      <inertia
        ixx="0.00227001457745611"
        ixy="2.85156961918549E-19"
        ixz="1.55854062294791E-19"
        iyy="0.00307476845816861"
        iyz="-4.01356065377951E-05"
        izz="0.00295129194888436" />
    </inertial>
    <visual>
      <origin
        xyz="0 0 0"
        rpy="0 0 0" />
      <geometry>
        <mesh
          filename="package://dvrk_model/LaprotekMaster/meshes/left_shoulder_link.STL" />
      </geometry>
      <material
        name="">
        <color
          rgba="0.792156862745098 0.819607843137255 0.933333333333333 1" />
      </material>
    </visual>
    <collision>
      <origin
        xyz="0 0 0"
        rpy="0 0 0" />
      <geometry>
        <mesh
          filename="package://dvrk_model/LaprotekMaster/meshes/left_shoulder_link.STL" />
      </geometry>
    </collision>
  </link>
  <joint
    name="left_shoulder_axis"
    type="revolute">
    <origin
      xyz="0.10736 -0.51763 0.26285"
      rpy="-1.5708 -5.452E-15 -1.5275" />
    <parent
      link="base_link" />
    <child
      link="left_shoulder_link" />
    <axis
      xyz="0 -1 0" />
    <limit
      lower="-3.14"
      upper="3.14"
      effort="0"
      velocity="0.1" />
  </joint>
  <link
    name="left_twist_joint">
    <inertial>
      <origin
        xyz="1.11610671260642E-08 2.80912593186855E-09 0.11113947170493"
        rpy="0 0 0" />
      <mass
        value="0.177470737055824" />
      <inertia
        ixx="0.000725141660105544"
        ixy="-1.73247016247422E-10"
        ixz="-1.0161920715827E-10"
        iyy="0.000733538481212379"
        iyz="-3.15489245430113E-12"
        izz="2.7152432856978E-05" />
    </inertial>
    <visual>
      <origin
        xyz="0 0 0"
        rpy="0 0 0" />
      <geometry>
        <mesh
          filename="package://dvrk_model/LaprotekMaster/meshes/left_twist_joint.STL" />
      </geometry>
      <material
        name="">
        <color
          rgba="0.792156862745098 0.819607843137255 0.933333333333333 1" />
      </material>
    </visual>
    <collision>
      <origin
        xyz="0 0 0"
        rpy="0 0 0" />
      <geometry>
        <mesh
          filename="package://dvrk_model/LaprotekMaster/meshes/left_twist_joint.STL" />
      </geometry>
    </collision>
  </link>
  <joint
    name="left_twist_axis"
    type="revolute">
    <origin
      xyz="0 0.056688 0.069621"
      rpy="-1.3021E-13 3.534E-14 -2.8761" />
    <parent
      link="left_shoulder_link" />
    <child
      link="left_twist_joint" />
    <axis
      xyz="0 0 1" />
    <limit
      lower="-3.14"
      upper="3.14"
      effort="0"
      velocity="0.1" />
  </joint>
  <link
    name="left_forarm_link">
    <inertial>
      <origin
        xyz="0.01051902490465 0.207088330582147 0.0273764305640486"
        rpy="0 0 0" />
      <mass
        value="0.0966291537515778" />
      <inertia
        ixx="0.000940179186405655"
        ixy="-0.00011122830309128"
        ixz="-4.03854354538683E-05"
        iyy="9.62268881882236E-05"
        iyz="-9.9182719468331E-05"
        izz="0.000949425756024447" />
    </inertial>
    <visual>
      <origin
        xyz="0 0 0"
        rpy="0 0 0" />
      <geometry>
        <mesh
          filename="package://dvrk_model/LaprotekMaster/meshes/left_forarm_link.STL" />
      </geometry>
      <material
        name="">
        <color
          rgba="0.752941176470588 0.752941176470588 0.752941176470588 1" />
      </material>
    </visual>
    <collision>
      <origin
        xyz="0 0 0"
        rpy="0 0 0" />
      <geometry>
        <mesh
          filename="package://dvrk_model/LaprotekMaster/meshes/left_forarm_link.STL" />
      </geometry>
    </collision>
  </link>
  <joint
    name="left_forarm_axis"
    type="revolute">
    <origin
      xyz="0.017359 -0.009525 0.18783"
      rpy="-2.1526 2.021E-15 1.5708" />
    <parent
      link="left_twist_joint" />
    <child
      link="left_forarm_link" />
    <axis
      xyz="1 0 0" />
    <limit
      lower="-3.14"
      upper="3.14"
      effort="0"
      velocity="0.1" />
  </joint>
  <link
    name="left_outer_joint">
    <inertial>
      <origin
        xyz="0.0691885086349239 -9.56371228832964E-06 0.059672839038751"
        rpy="0 0 0" />
      <mass
        value="0.12416246800254" />
      <inertia
        ixx="9.04822661334576E-05"
        ixy="4.15318437417014E-08"
        ixz="6.18252466116717E-05"
        iyy="0.00022042336788377"
        iyz="-6.48989851775237E-08"
        izz="0.000142666736441151" />
    </inertial>
    <visual>
      <origin
        xyz="0 0 0"
        rpy="0 0 0" />
      <geometry>
        <mesh
          filename="package://dvrk_model/LaprotekMaster/meshes/left_outer_joint.STL" />
      </geometry>
      <material
        name="">
        <color
          rgba="0.752941176470588 0.752941176470588 0.752941176470588 1" />
      </material>
    </visual>
    <collision>
      <origin
        xyz="0 0 0"
        rpy="0 0 0" />
      <geometry>
        <mesh
          filename="package://dvrk_model/LaprotekMaster/meshes/left_outer_joint.STL" />
      </geometry>
    </collision>
  </link>
  <joint
    name="left_outer_axis"
    type="revolute">
    <origin
      xyz="0.11605 0.25967 -0.031151"
      rpy="-2.6796 -0.7854 3.1416" />
    <parent
      link="left_forarm_link" />
    <child
      link="left_outer_joint" />
    <axis
      xyz="-1 0 0" />
    <limit
      lower="-3.14"
      upper="3.14"
      effort="0"
      velocity="0.1" />
  </joint>
  <link
    name="left_inner_link">
    <inertial>
      <origin
        xyz="0.0603085564152763 9.98528203732807E-06 -0.0785354800987832"
        rpy="0 0 0" />
      <mass
        value="0.130072358006885" />
      <inertia
        ixx="0.000183138639758366"
        ixy="5.38918330723531E-08"
        ixz="-6.46921769582806E-05"
        iyy="0.000261683160501651"
        iyz="-1.86926072937141E-08"
        izz="9.22392132071116E-05" />
    </inertial>
    <visual>
      <origin
        xyz="0 0 0"
        rpy="0 0 0" />
      <geometry>
        <mesh
          filename="package://dvrk_model/LaprotekMaster/meshes/left_inner_link.STL" />
      </geometry>
      <material
        name="">
        <color
          rgba="0.752941176470588 0.752941176470588 0.752941176470588 1" />
      </material>
    </visual>
    <collision>
      <origin
        xyz="0 0 0"
        rpy="0 0 0" />
      <geometry>
        <mesh
          filename="package://dvrk_model/LaprotekMaster/meshes/left_inner_link.STL" />
      </geometry>
    </collision>
  </link>
  <joint
    name="left_inner_axis"
    type="revolute">
    <origin
      xyz="0 0 0"
      rpy="-3.1416 -3.8759E-15 0.47178" />
    <parent
      link="left_outer_joint" />
    <child
      link="left_inner_link" />
    <axis
      xyz="0 0 1" />
    <limit
      lower="-3.14"
      upper="3.14"
      effort="0"
      velocity="0.1" />
  </joint>
  <link
    name="left_grip_link">
    <inertial>
      <origin
        xyz="-0.0179723725555376 -0.00305537126820352 0.0681033056001612"
        rpy="0 0 0" />
      <mass
        value="0.127389218766117" />
      <inertia
        ixx="5.36394966168107E-05"
        ixy="-1.41366804198005E-05"
        ixz="1.72600602867352E-05"
        iyy="0.000202644152688777"
        iyz="5.74822786826609E-06"
        izz="0.000189903300506405" />
    </inertial>
    <visual>
      <origin
        xyz="0 0 0"
        rpy="0 0 0" />
      <geometry>
        <mesh
          filename="package://dvrk_model/LaprotekMaster/meshes/left_grip_link.STL" />
      </geometry>
      <material
        name="">
        <color
          rgba="0.752941176470588 0.752941176470588 0.752941176470588 1" />
      </material>
    </visual>
    <collision>
      <origin
        xyz="0 0 0"
        rpy="0 0 0" />
      <geometry>
        <mesh
          filename="package://dvrk_model/LaprotekMaster/meshes/left_grip_link.STL" />
      </geometry>
    </collision>
  </link>
  <joint
    name="left_grip_axis"
    type="revolute">
    <origin
      xyz="0.065119 0 -0.0006985"
      rpy="1.5708 0.49008 -1.5708" />
    <parent
      link="left_inner_link" />
    <child
      link="left_grip_link" />
    <axis
      xyz="0 0 1" />
    <limit
      lower="-3.14"
      upper="3.14"
      effort="0"
      velocity="0.1" />
  </joint>
  <link
    name="left_thumb_link">
    <inertial>
      <origin
        xyz="-0.00190398713461787 0.0260728182964867 -0.0370018707000022"
        rpy="0 0 0" />
      <mass
        value="0.0140914985197406" />
      <inertia
        ixx="6.65725718029998E-06"
        ixy="3.26121367863419E-07"
        ixz="7.2096032225756E-07"
        iyy="6.68801632416988E-06"
        iyz="-8.82356958748302E-07"
        izz="1.40018785328935E-06" />
    </inertial>
    <visual>
      <origin
        xyz="0 0 0"
        rpy="0 0 0" />
      <geometry>
        <mesh
          filename="package://dvrk_model/LaprotekMaster/meshes/left_thumb_link.STL" />
      </geometry>
      <material
        name="">
        <color
          rgba="0.501960784313725 0.501960784313725 1 1" />
      </material>
    </visual>
    <collision>
      <origin
        xyz="0 0 0"
        rpy="0 0 0" />
      <geometry>
        <mesh
          filename="package://dvrk_model/LaprotekMaster/meshes/left_thumb_link.STL" />
      </geometry>
    </collision>
  </link>
  <joint
    name="left_thumb_axis"
    type="revolute">
    <origin
      xyz="-0.025537 -0.02921 0.073025"
      rpy="-6.1912E-15 -0.77622 1.5708" />
    <parent
      link="left_grip_link" />
    <child
      link="left_thumb_link" />
    <axis
      xyz="0 1 0" />
    <limit
      lower="-3.14"
      upper="3.14"
      effort="0"
      velocity="0.1" />
  </joint>
  <link
    name="right_shoulder_link">
    <inertial>
      <origin
        xyz="1.11022302462516E-16 0.0497615591942104 0.00732049360916456"
        rpy="0 0 0" />
      <mass
        value="1.34463372754833" />
      <inertia
        ixx="0.00227001457745611"
        ixy="-4.01779650214998E-19"
        ixz="2.79859685772821E-18"
        iyy="0.00307476845816861"
        iyz="-4.0135606537798E-05"
        izz="0.00295129194888436" />
    </inertial>
    <visual>
      <origin
        xyz="0 0 0"
        rpy="0 0 0" />
      <geometry>
        <mesh
          filename="package://dvrk_model/LaprotekMaster/meshes/right_shoulder_link.STL" />
      </geometry>
      <material
        name="">
        <color
          rgba="0.792156862745098 0.819607843137255 0.933333333333333 1" />
      </material>
    </visual>
    <collision>
      <origin
        xyz="0 0 0"
        rpy="0 0 0" />
      <geometry>
        <mesh
          filename="package://dvrk_model/LaprotekMaster/meshes/right_shoulder_link.STL" />
      </geometry>
    </collision>
  </link>
  <joint
    name="right_shoulder_axis"
    type="revolute">
    <origin
      xyz="0.107358623973539 0.521451551444158 0.272850099480564"
      rpy="-1.57079632679501 -5.03301002676894E-15 -1.61397342737463" />
    <parent
      link="base_link" />
    <child
      link="right_shoulder_link" />
    <axis
      xyz="0 1 0" />
    <limit
      lower="-3.14"
      upper="3.14"
      effort="0"
      velocity="0.1" />
  </joint>
  <link
    name="right_twist_link">
    <inertial>
      <origin
        xyz="-9.11755632104772E-09 9.92149051803892E-09 0.11113946165402"
        rpy="0 0 0" />
      <mass
        value="0.1774707061369" />
      <inertia
        ixx="0.000725141576368758"
        ixy="-1.94521232102637E-10"
        ixz="9.00945688938696E-11"
        iyy="0.000733538345580548"
        iyz="-8.85411495261679E-11"
        izz="2.71524052804197E-05" />
    </inertial>
    <visual>
      <origin
        xyz="0 0 0"
        rpy="0 0 0" />
      <geometry>
        <mesh
          filename="package://dvrk_model/LaprotekMaster/meshes/right_twist_link.STL" />
      </geometry>
      <material
        name="">
        <color
          rgba="0.792156862745098 0.819607843137255 0.933333333333333 1" />
      </material>
    </visual>
    <collision>
      <origin
        xyz="0 0 0"
        rpy="0 0 0" />
      <geometry>
        <mesh
          filename="package://dvrk_model/LaprotekMaster/meshes/right_twist_link.STL" />
      </geometry>
    </collision>
  </link>
  <joint
    name="right_twist_axis"
    type="revolute">
    <origin
      xyz="0 0.0666876999999924 0.0696214000000075"
      rpy="-1.05819866758061E-13 -3.46736528378244E-14 2.87619529855606" />
    <parent
      link="right_shoulder_link" />
    <child
      link="right_twist_link" />
    <axis
      xyz="0 0 -1" />
    <limit
      lower="-3.14"
      upper="3.14"
      effort="0"
      velocity="0.1" />
  </joint>
  <link
    name="right_forarm_link">
    <inertial>
      <origin
        xyz="0.0105301064085111 0.207116232797857 -0.0117869054233155"
        rpy="0 0 0" />
      <mass
        value="0.0966291480256091" />
      <inertia
        ixx="0.000940483665179772"
        ixy="-0.000111357218630274"
        ixz="4.04021242842948E-05"
        iyy="9.63216918604192E-05"
        iyz="9.96956798609406E-05"
        izz="0.000949780530694288" />
    </inertial>
    <visual>
      <origin
        xyz="0 0 0"
        rpy="0 0 0" />
      <geometry>
        <mesh
          filename="package://dvrk_model/LaprotekMaster/meshes/right_forarm_link.STL" />
      </geometry>
      <material
        name="">
        <color
          rgba="0.752941176470588 0.752941176470588 0.752941176470588 1" />
      </material>
    </visual>
    <collision>
      <origin
        xyz="0 0 0"
        rpy="0 0 0" />
      <geometry>
        <mesh
          filename="package://dvrk_model/LaprotekMaster/meshes/right_forarm_link.STL" />
      </geometry>
    </collision>
  </link>
  <joint
    name="right_forarm_axis"
    type="revolute">
    <origin
      xyz="-0.00432116773035734 -0.00952499999999984 0.179255476761797"
      rpy="-0.989100133780909 -2.46157261241109E-15 1.5707963267949" />
    <parent
      link="right_twist_link" />
    <child
      link="right_forarm_link" />
    <axis
      xyz="-1 0 0" />
      <limit
        lower="-3.14"
        upper="3.14"
        effort="0"
        velocity="0.1" />
  </joint>
  <link
    name="right_outer_link">
    <inertial>
      <origin
        xyz="0.0691885098884718 -9.5663340904939E-06 0.0596728359877448"
        rpy="0 0 0" />
      <mass
        value="0.12416247486456" />
      <inertia
        ixx="9.04822875907308E-05"
        ixy="4.15390332556985E-08"
        ixz="6.18252555176357E-05"
        iyy="0.000220423393533131"
        iyz="-6.49157306140668E-08"
        izz="0.000142666742597573" />
    </inertial>
    <visual>
      <origin
        xyz="0 0 0"
        rpy="0 0 0" />
      <geometry>
        <mesh
          filename="package://dvrk_model/LaprotekMaster/meshes/right_outer_link.STL" />
      </geometry>
      <material
        name="">
        <color
          rgba="0.752941176470588 0.752941176470588 0.752941176470588 1" />
      </material>
    </visual>
    <collision>
      <origin
        xyz="0 0 0"
        rpy="0 0 0" />
      <geometry>
        <mesh
          filename="package://dvrk_model/LaprotekMaster/meshes/right_outer_link.STL" />
      </geometry>
    </collision>
  </link>
  <joint
    name="right_outer_axis"
    type="revolute">
    <origin
      xyz="0.116054251920652 0.259672653491981 0.04675320503359"
      rpy="-0.462044223418388 0.785398163397446 -3.14159265358979" />
    <parent
      link="right_forarm_link" />
    <child
      link="right_outer_link" />
    <axis
      xyz="-1 0 0" />
      <limit
        lower="-3.14"
        upper="3.14"
        effort="0"
        velocity="0.1" />
  </joint>
  <link
    name="right_inner_link">
    <inertial>
      <origin
        xyz="0.0602826607372846 9.98983350863902E-06 -0.0785354823171768"
        rpy="0 0 0" />
      <mass
        value="0.130072367248991" />
      <inertia
        ixx="0.000183138646981063"
        ixy="5.39193792873903E-08"
        ixz="-6.46921890674535E-05"
        iyy="0.000261683198722478"
        iyz="-1.86776672375943E-08"
        izz="9.22392481028234E-05" />
    </inertial>
    <visual>
      <origin
        xyz="0 0 0"
        rpy="0 0 0" />
      <geometry>
        <mesh
          filename="package://dvrk_model/LaprotekMaster/meshes/right_inner_link.STL" />
      </geometry>
      <material
        name="">
        <color
          rgba="0.752941176470588 0.752941176470588 0.752941176470588 1" />
      </material>
    </visual>
    <collision>
      <origin
        xyz="0 0 0"
        rpy="0 0 0" />
      <geometry>
        <mesh
          filename="package://dvrk_model/LaprotekMaster/meshes/right_inner_link.STL" />
      </geometry>
    </collision>
  </link>
  <joint
    name="right_inner_axis"
    type="fixed">
    <origin
      xyz="0 0 0"
      rpy="3.14159265358887 1.98203565121497E-15 -0.471889922187409" />
    <parent
      link="right_outer_link" />
    <child
      link="right_inner_link" />
    <axis
      xyz="0 0 0" />
      <limit
        lower="-3.14"
        upper="3.14"
        effort="0"
        velocity="0.1" />
  </joint>

  <link
    name="right_grip_link">
    <inertial>
      <origin
        xyz="0.00559637238492722 0.0798999528825071 -0.00192636875931732"
        rpy="0 0 0" />
      <mass
        value="0.12500818504158" />
      <inertia
        ixx="0.000202308496845487"
        ixy="3.95844840109998E-08"
        ixz="5.14806081623282E-06"
        iyy="5.38536262456598E-05"
        iyz="-2.20454950762829E-05"
        izz="0.000188434086978825" />
    </inertial>
    <visual>
      <origin
        xyz="0 0 0"
        rpy="0 0 0" />
      <geometry>
        <mesh
          filename="package://dvrk_model/LaprotekMaster/meshes/right_grip_link.STL" />
      </geometry>
      <material
        name="">
        <color
          rgba="0.752941176470588 0.752941176470588 0.752941176470588 1" />
      </material>
    </visual>
    <collision>
      <origin
        xyz="0 0 0"
        rpy="0 0 0" />
      <geometry>
        <mesh
          filename="package://dvrk_model/LaprotekMaster/meshes/right_grip_link.STL" />
      </geometry>
    </collision>
  </link>
  <joint
    name="right_grip_axis"
    type="revolute">
    <origin
      xyz="-0.00793139546805466 0.0549050123843542 -0.0299894490800136"
      rpy="2.448856438822 0.742158838609391 -0.511207263500882" />
    <parent
      link="right_inner_link" />
    <child
      link="right_grip_link" />
    <axis
      xyz="-0.642787609686614 0 0.766044443118915" />
      <limit
        lower="-3.14"
        upper="3.14"
        effort="0"
        velocity="0.1" />
  </joint>
  <link
    name="right_thumb_link">
    <inertial>
      <origin
        xyz="0.0366949952927325 -0.00512167791651025 0.0260728368504085"
        rpy="0 0 0" />
      <mass
        value="0.0140914657117832" />
      <inertia
        ixx="1.31493181580504E-06"
        ixy="-2.5356881506934E-07"
        ixz="9.07426974378962E-07"
        iyy="6.74252876425963E-06"
        iyz="2.47979836920417E-07"
        izz="6.68803258816822E-06" />
    </inertial>
    <visual>
      <origin
        xyz="0 0 0"
        rpy="0 0 0" />
      <geometry>
        <mesh
          filename="package://dvrk_model/LaprotekMaster/meshes/right_thumb_link.STL" />
      </geometry>
      <material
        name="">
        <color
          rgba="0.941176470588235 0.674509803921569 0.117647058823529 1" />
      </material>
    </visual>
    <collision>
      <origin
        xyz="0 0 0"
        rpy="0 0 0" />
      <geometry>
        <mesh
          filename="package://dvrk_model/LaprotekMaster/meshes/right_thumb_link.STL" />
      </geometry>
    </collision>
  </link>
  <joint
    name="right_thumb_axis"
    type="revolute">
    <origin
      xyz="0.0223761581835059 0.0877673733559149 0.018775826078943"
      rpy="1.57079632679485 1.38701724134735 3.14159265358975" />
    <parent
      link="right_grip_link" />
    <child
      link="right_thumb_link" />
    <axis
      xyz="0 0 -1" />
      <limit
        lower="-3.14"
        upper="3.14"
        effort="0"
        velocity="0.1" />
  </joint>
</robot>
