<sdf version='1.6'>
  <model name='master'>
    <link name='left_top_panel'>
      <pose frame=''>-0.25 0 1 0 -0 0</pose>
      <inertial>
        <pose frame=''>0 0 0 0 -0 0</pose>
        <mass>0.9</mass>
        <inertia>
          <ixx>9</ixx>
          <ixy>0</ixy>
          <ixz>0</ixz>
          <iyy>9</iyy>
          <iyz>0</iyz>
          <izz>9</izz>
        </inertia>
      </inertial>
      <collision name='left_top_panel_collision'>
        <pose frame=''>0 0 0 0 -0 0</pose>
        <geometry>
          <mesh>
            <scale>1 1 1</scale>
            <uri>model://dvrk_description/mtm/meshes/Top Panel.STL</uri>
          </mesh>
        </geometry>
      </collision>
      <visual name='left_top_panel_visual'>
        <pose frame=''>0 0 0 0 -0 0</pose>
        <geometry>
          <mesh>
            <scale>1 1 1</scale>
            <uri>model://dvrk_description/mtm/meshes/Top Panel.dae</uri>
          </mesh>
        </geometry>
      </visual>
    </link>
    <joint name='left_fixed_joint' type='fixed'>
      <child>left_top_panel</child>
      <parent>world</parent>
    </joint>
    <link name='left_outer_yaw_link'>
      <pose frame=''>-0.25 0 1 0 -0 1.5708</pose>
      <inertial>
        <pose frame=''>0 0 0 0 -0 0</pose>
        <mass>1</mass>
        <inertia>
          <ixx>10</ixx>
          <ixy>0</ixy>
          <ixz>0</ixz>
          <iyy>10</iyy>
          <iyz>0</iyz>
          <izz>10</izz>
        </inertia>
      </inertial>
      <collision name='left_outer_yaw_link_collision'>
        <pose frame=''>0 0 0 0 -0 0</pose>
        <geometry>
          <mesh>
            <scale>1 1 1</scale>
            <uri>model://dvrk_description/mtm/meshes/OutPitch_Shoulder.STL</uri>
          </mesh>
        </geometry>
      </collision>
      <visual name='left_outer_yaw_link_visual'>
        <pose frame=''>0 0 0 0 -0 0</pose>
        <geometry>
          <mesh>
            <scale>1 1 1</scale>
            <uri>model://dvrk_description/mtm/meshes/OutPitch_Shoulder.dae</uri>
          </mesh>
        </geometry>
      </visual>
    </link>
    <joint name='left_outer_yaw_joint' type='revolute'>
      <child>left_outer_yaw_link</child>
      <parent>left_top_panel</parent>
      <axis>
        <xyz>0 0 1</xyz>
        <limit>
          <lower>-1.309</lower>
          <upper>0.785398</upper>
          <effort>50</effort>
          <velocity>2</velocity>
        </limit>
        <dynamics>
          <spring_reference>0</spring_reference>
          <spring_stiffness>0</spring_stiffness>
        </dynamics>
        <use_parent_model_frame>1</use_parent_model_frame>
      </axis>
    </joint>
    <link name='left_back_parallel_link'>
      <pose frame=''>-0.25 0 0.80963 3.14159 -1.57079 -3.14159</pose>
      <inertial>
        <pose frame=''>0 0 0 0 -0 0</pose>
        <mass>0.9</mass>
        <inertia>
          <ixx>9</ixx>
          <ixy>0</ixy>
          <ixz>0</ixz>
          <iyy>9</iyy>
          <iyz>0</iyz>
          <izz>9</izz>
        </inertia>
      </inertial>
      <collision name='left_back_parallel_link_collision'>
        <pose frame=''>0 0 0 0 -0 0</pose>
        <geometry>
          <mesh>
            <scale>1 1 1</scale>
            <uri>model://dvrk_description/mtm/meshes/ArmParallel.STL</uri>
          </mesh>
        </geometry>
      </collision>
      <visual name='left_back_parallel_link_visual'>
        <pose frame=''>0 0 0 0 -0 0</pose>
        <geometry>
          <mesh>
            <scale>1 1 1</scale>
            <uri>model://dvrk_description/mtm/meshes/ArmParallel.dae</uri>
          </mesh>
        </geometry>
      </visual>
    </link>
    <joint name='left_shoulder_pitch_joint' type='revolute'>
      <child>left_back_parallel_link</child>
      <parent>left_outer_yaw_link</parent>
      <axis>
        <xyz>-1 0 0</xyz>
        <limit>
          <lower>-0.785398</lower>
          <upper>0.785398</upper>
          <effort>100</effort>
          <velocity>10</velocity>
        </limit>
        <dynamics>
          <spring_reference>0</spring_reference>
          <spring_stiffness>0</spring_stiffness>
        </dynamics>
        <use_parent_model_frame>1</use_parent_model_frame>
      </axis>
    </joint>
    <link name='left_bottom_parallel_link'>
      <pose frame=''>-0.25 -0 0.53023 -1.5708 0 1.5708</pose>
      <inertial>
        <pose frame=''>0 0 0 0 -0 0</pose>
        <mass>0.8</mass>
        <inertia>
          <ixx>0.1</ixx>
          <ixy>0</ixy>
          <ixz>0</ixz>
          <iyy>0.1</iyy>
          <iyz>0</iyz>
          <izz>0.1</izz>
        </inertia>
      </inertial>
      <collision name='left_bottom_parallel_link_collision'>
        <pose frame=''>0 0 0 0 -0 0</pose>
        <geometry>
          <mesh>
            <scale>1 1 1</scale>
            <uri>model://dvrk_description/mtm/meshes/BottomArm.STL</uri>
          </mesh>
        </geometry>
      </collision>
      <visual name='left_bottom_parallel_link_visual'>
        <pose frame=''>0 0 0 0 -0 0</pose>
        <geometry>
          <mesh>
            <scale>1 1 1</scale>
            <uri>model://dvrk_description/mtm/meshes/BottomArm.dae</uri>
          </mesh>
        </geometry>
      </visual>
    </link>
    <joint name='left_elbow_pitch_joint' type='revolute'>
      <child>left_bottom_parallel_link</child>
      <parent>left_back_parallel_link</parent>
      <axis>
        <xyz>-1 0 0</xyz>
        <limit>
          <lower>-0.785398</lower>
          <upper>0.785398</upper>
          <effort>100</effort>
          <velocity>10</velocity>
        </limit>
        <dynamics>
          <spring_reference>0</spring_reference>
          <spring_stiffness>0</spring_stiffness>
        </dynamics>
        <use_parent_model_frame>1</use_parent_model_frame>
      </axis>
    </joint>
    <link name='left_wrist_platform_link'>
      <pose frame=''>-0.25 -0.3645 0.68623 -0 -0 1.5708</pose>
      <inertial>
        <pose frame=''>0 0 0 0 -0 0</pose>
        <mass>0.4</mass>
        <inertia>
          <ixx>0.1</ixx>
          <ixy>0</ixy>
          <ixz>0</ixz>
          <iyy>0.1</iyy>
          <iyz>0</iyz>
          <izz>0.1</izz>
        </inertia>
      </inertial>
      <collision name='left_wrist_platform_link_collision'>
        <pose frame=''>0 0 0 0 -0 0</pose>
        <geometry>
          <mesh>
            <scale>1 1 1</scale>
            <uri>model://dvrk_description/mtm/meshes/WristPlatform.STL</uri>
          </mesh>
        </geometry>
      </collision>
      <visual name='left_wrist_platform_link_visual'>
        <pose frame=''>0 0 0 0 -0 0</pose>
        <geometry>
          <mesh>
            <scale>1 1 1</scale>
            <uri>model://dvrk_description/mtm/meshes/WristPlatform.dae</uri>
          </mesh>
        </geometry>
      </visual>
    </link>
    <joint name='left_wrist_platform_joint' type='revolute'>
      <child>left_wrist_platform_link</child>
      <parent>left_bottom_parallel_link</parent>
      <axis>
        <xyz>-0 -0 1</xyz>
        <limit>
          <lower>-1.0472</lower>
          <upper>4.27606</upper>
          <effort>100</effort>
          <velocity>10</velocity>
        </limit>
        <dynamics>
          <spring_reference>0</spring_reference>
          <spring_stiffness>0</spring_stiffness>
        </dynamics>
        <use_parent_model_frame>1</use_parent_model_frame>
      </axis>
    </joint>
    <link name='left_wrist_pitch_link'>
      <pose frame=''>-0.25 -0.3645 0.68623 -1.5708 0 1.5708</pose>
      <inertial>
        <pose frame=''>0 0 0 0 -0 0</pose>
        <mass>0.2</mass>
        <inertia>
          <ixx>0.1</ixx>
          <ixy>0</ixy>
          <ixz>0</ixz>
          <iyy>0.1</iyy>
          <iyz>0</iyz>
          <izz>0.1</izz>
        </inertia>
      </inertial>
      <collision name='left_wrist_pitch_link_collision'>
        <pose frame=''>0 0 0 0 -0 0</pose>
        <geometry>
          <mesh>
            <scale>1 1 1</scale>
            <uri>model://dvrk_description/mtm/meshes/WristPitch.STL</uri>
          </mesh>
        </geometry>
      </collision>
      <visual name='left_wrist_pitch_link_visual'>
        <pose frame=''>0 0 0 0 -0 0</pose>
        <geometry>
          <mesh>
            <scale>1 1 1</scale>
            <uri>model://dvrk_description/mtm/meshes/WristPitch.dae</uri>
          </mesh>
        </geometry>
      </visual>
    </link>
    <joint name='left_wrist_pitch_joint' type='revolute'>
      <child>left_wrist_pitch_link</child>
      <parent>left_wrist_platform_link</parent>
      <axis>
        <xyz>-1 0 -0</xyz>
        <limit>
          <lower>-1.5708</lower>
          <upper>3.14159</upper>
          <effort>100</effort>
          <velocity>10</velocity>
        </limit>
        <dynamics>
          <spring_reference>0</spring_reference>
          <spring_stiffness>0</spring_stiffness>
        </dynamics>
        <use_parent_model_frame>1</use_parent_model_frame>
      </axis>
    </joint>
    <link name='left_wrist_yaw_link'>
      <pose frame=''>-0.25 -0.3645 0.68623 -0 0 3.14159</pose>
      <inertial>
        <pose frame=''>0 0 0 0 -0 0</pose>
        <mass>0.2</mass>
        <inertia>
          <ixx>0.1</ixx>
          <ixy>0</ixy>
          <ixz>0</ixz>
          <iyy>0.1</iyy>
          <iyz>0</iyz>
          <izz>0.1</izz>
        </inertia>
      </inertial>
      <collision name='left_wrist_yaw_link_collision'>
        <pose frame=''>0 0 0 0 -0 0</pose>
        <geometry>
          <mesh>
            <scale>1 1 1</scale>
            <uri>model://dvrk_description/mtm/meshes/WristYaw.STL</uri>
          </mesh>
        </geometry>
      </collision>
      <visual name='left_wrist_yaw_link_visual'>
        <pose frame=''>0 0 0 0 -0 0</pose>
        <geometry>
          <mesh>
            <scale>1 1 1</scale>
            <uri>model://dvrk_description/mtm/meshes/WristYaw.dae</uri>
          </mesh>
        </geometry>
      </visual>
    </link>
    <joint name='left_wrist_yaw_joint' type='revolute'>
      <child>left_wrist_yaw_link</child>
      <parent>left_wrist_pitch_link</parent>
      <axis>
        <xyz>-0 -0 1</xyz>
        <limit>
          <lower>-0.785398</lower>
          <upper>0.785398</upper>
          <effort>100</effort>
          <velocity>10</velocity>
        </limit>
        <dynamics>
          <spring_reference>0</spring_reference>
          <spring_stiffness>0</spring_stiffness>
        </dynamics>
        <use_parent_model_frame>1</use_parent_model_frame>
      </axis>
    </joint>
    <link name='left_wrist_roll_link'>
      <pose frame=''>-0.25 -0.3255 0.68623 -1.57079 1.57079 3.14159</pose>
      <inertial>
        <pose frame=''>0 0 0 0 -0 0</pose>
        <mass>0.1</mass>
        <inertia>
          <ixx>0.1</ixx>
          <ixy>0</ixy>
          <ixz>0</ixz>
          <iyy>0.1</iyy>
          <iyz>0</iyz>
          <izz>0.1</izz>
        </inertia>
      </inertial>
      <collision name='left_wrist_roll_link_collision'>
        <pose frame=''>0 0 0 0 -0 0</pose>
        <geometry>
          <mesh>
            <scale>1 1 1</scale>
            <uri>model://dvrk_description/mtm/meshes/WristRoll.STL</uri>
          </mesh>
        </geometry>
      </collision>
      <visual name='left_wrist_roll_link_visual'>
        <pose frame=''>0 0 0 0 -0 0</pose>
        <geometry>
          <mesh>
            <scale>1 1 1</scale>
            <uri>model://dvrk_description/mtm/meshes/WristRoll.dae</uri>
          </mesh>
        </geometry>
      </visual>
    </link>
    <joint name='left_wrist_roll_joint' type='revolute'>
      <child>left_wrist_roll_link</child>
      <parent>left_wrist_yaw_link</parent>
      <axis>
        <xyz>0 1 0</xyz>
        <limit>
          <lower>-4.71239</lower>
          <upper>4.71239</upper>
          <effort>100</effort>
          <velocity>10</velocity>
        </limit>
        <dynamics>
          <spring_reference>0</spring_reference>
          <spring_stiffness>0</spring_stiffness>
        </dynamics>
        <use_parent_model_frame>1</use_parent_model_frame>
      </axis>
    </joint>
    <link name='left_top_parallel_link'>
      <pose frame=''>-0.315 0 0.80963 1.5708 -0 -1.5708</pose>
      <inertial>
        <pose frame=''>0 0 0 0 -0 0</pose>
        <mass>0.5</mass>
        <inertia>
          <ixx>5</ixx>
          <ixy>0</ixy>
          <ixz>0</ixz>
          <iyy>5</iyy>
          <iyz>0</iyz>
          <izz>5</izz>
        </inertia>
      </inertial>
      <collision name='left_top_parallel_link_collision'>
        <pose frame=''>0 0 0 0 -0 0</pose>
        <geometry>
          <mesh>
            <scale>1 1 1</scale>
            <uri>model://dvrk_description/mtm/meshes/ArmParallel1.STL</uri>
          </mesh>
        </geometry>
      </collision>
      <visual name='left_top_parallel_link_visual'>
        <pose frame=''>0 0 0 0 -0 0</pose>
        <geometry>
          <mesh>
            <scale>1 1 1</scale>
            <uri>model://dvrk_description/mtm/meshes/ArmParallel1.dae</uri>
          </mesh>
        </geometry>
      </visual>
    </link>
    <joint name='left_shoulder_pitch_parallel_joint' type='revolute'>
      <child>left_top_parallel_link</child>
      <parent>left_back_parallel_link</parent>
      <axis>
        <xyz>-1 0 0</xyz>
        <limit>
          <lower>-1.5708</lower>
          <upper>1.5708</upper>
          <effort>100</effort>
          <velocity>10</velocity>
        </limit>
        <dynamics>
          <spring_reference>0</spring_reference>
          <spring_stiffness>0</spring_stiffness>
        </dynamics>
        <use_parent_model_frame>1</use_parent_model_frame>
      </axis>
    </joint>
    <static>0</static>
    <plugin name='force_torque_sensor' filename='libgazebo_ros_f3d.so'>
      <bodyName>left_bottom_parallel_link</bodyName>
      <frameName>left_bottom_parallel_link</frameName>
      <topicName>/force_torque_feedback</topicName>
      <alwaysOn>true</alwaysOn>
      <updateRate>100.0</updateRate>
    </plugin>
    <plugin name='dvrk_plugin' filename='libdvrk_plugin.so'/>
  </model>
</sdf>
