<?xml version="1.0"?>

<robot name="suj" xmlns:xacro="http://www.ros.org/wiki/xacro">

<xacro:macro name="suj" params="prefix">

<property name="damping" value="0.2"/>
<property name="friction" value="1"/>

<link name="world"/>
<joint name="${prefix}fixed" type="fixed">
<origin
  xyz="0 0 0.167458"
  rpy="0 0 0" />
<parent link="world"/>
<child link="${prefix}base_link"/>
</joint>

  <link
    name="${prefix}base_link">
    <inertial>
      <origin
        xyz="0 -0.163432953037324 0.552457766148795"
        rpy="0 0 0" />
      <mass
        value="251.331338880703" />
      <inertia
        ixx="116.092010218379"
        ixy="0"
        ixz="0"
        iyy="116.786187825287"
        iyz="-2.79449977491914"
        izz="20.7204503058012" />
    </inertial>
    <visual>
      <origin
        xyz="0 0 0"
        rpy="0 0 0" />
      <geometry>
        <mesh
          filename="package://dvrk_description/suj/meshes/base_link.STL" />
      </geometry>
      <material
        name="">
        <color
          rgba="0.647058823529412 0.619607843137255 0.588235294117647 1" />
      </material>
    </visual>
    <collision>
      <origin
        xyz="0 0 0"
        rpy="0 0 0" />
      <geometry>
        <mesh
          filename="package://dvrk_description/suj/meshes/base_link.STL" />
      </geometry>
    </collision>
  </link>
  <link
    name="${prefix}suj_psm2_L0">
    <inertial>
      <origin
        xyz="0.0568399826690053 0 0.148466700879736"
        rpy="0 0 0" />
      <mass
        value="8.19045158700103" />
      <inertia
        ixx="0.0849399138017183"
        ixy="0"
        ixz="-0.00950408519583723"
        iyy="0.0840388037894648"
        iyz="0"
        izz="0.0337578517914833" />
    </inertial>
    <visual>
      <origin
        xyz="0 0 0"
        rpy="0 0 0" />
      <geometry>
        <mesh
          filename="package://dvrk_description/suj/meshes/suj_psm2_L0.STL" />
      </geometry>
      <material
        name="">
        <color
          rgba="0.792156862745098 0.819607843137255 0.933333333333333 1" />
      </material>
    </visual>
    <collision>
      <origin
        xyz="0 0 0"
        rpy="0 0 0" />
      <geometry>
        <mesh
          filename="package://dvrk_description/suj/meshes/suj_psm2_L0.STL" />
      </geometry>
    </collision>
  </link>
  <joint
    name="${prefix}suj_psm2_J0"
    type="prismatic">
    <origin
      xyz="0.1912 -0.101599999999999 0.761099999999999"
      rpy="-3.14159265358979 0 3.14159265358979" />
    <parent
      link="${prefix}base_link" />
    <child
      link="${prefix}suj_psm2_L0" />
    <axis
      xyz="0 0 -1" />
  <limit
      lower="-0.3798"
      upper="0.8425"
      effort="50"
      velocity="50" />
  </joint>
  <link
    name="${prefix}suj_psm2_L1">
    <inertial>
      <origin
        xyz="0 0.181423473764042 -0.108873680906329"
        rpy="0 0 0" />
      <mass
        value="4.285154468433" />
      <inertia
        ixx="0.165298975805322"
        ixy="0"
        ixz="0"
        iyy="0.0318879130435778"
        iyz="-0.0216382058279061"
        izz="0.151812373014208" />
    </inertial>
    <visual>
      <origin
        xyz="0 0 0"
        rpy="0 0 0" />
      <geometry>
        <mesh
          filename="package://dvrk_description/suj/meshes/suj_psm2_L1.STL" />
      </geometry>
      <material
        name="">
        <color
          rgba="0.792156862745098 0.819607843137255 0.933333333333333 1" />
      </material>
    </visual>
    <collision>
      <origin
        xyz="0 0 0"
        rpy="0 0 0" />
      <geometry>
        <mesh
          filename="package://dvrk_description/suj/meshes/suj_psm2_L1.STL" />
      </geometry>
    </collision>
  </link>
  <joint
    name="${prefix}suj_psm2_J1"
    type="continuous">
    <origin
      xyz="0 0 0"
      rpy="0 0 1.5707963267949" />
    <parent
      link="${prefix}suj_psm2_L0" />
    <child
      link="${prefix}suj_psm2_L1" />
    <axis
      xyz="0 0 -1" />
  </joint>
  <link
    name="${prefix}suj_psm2_L2">
    <inertial>
      <origin
        xyz="0.208919873467034 0 0.0907666144838899"
        rpy="0 0 0" />
      <mass
        value="3.37391295638727" />
      <inertia
        ixx="0.0170495937307872"
        ixy="0"
        ixz="0.0010255647636027"
        iyy="0.12264804166409"
        iyz="0"
        izz="0.114779656818464" />
    </inertial>
    <visual>
      <origin
        xyz="0 0 0"
        rpy="0 0 0" />
      <geometry>
        <mesh
          filename="package://dvrk_description/suj/meshes/suj_psm2_L2.STL" />
      </geometry>
      <material
        name="">
        <color
          rgba="0.792156862745098 0.819607843137255 0.933333333333333 1" />
      </material>
    </visual>
    <collision>
      <origin
        xyz="0 0 0"
        rpy="0 0 0" />
      <geometry>
        <mesh
          filename="package://dvrk_description/suj/meshes/suj_psm2_L2.STL" />
      </geometry>
    </collision>
  </link>
  <joint
    name="${prefix}suj_psm2_J2"
    type="continuous">
    <origin
      xyz="0 0.4318 -0.17125"
      rpy="3.14159265358979 0 1.5707963267949" />
    <parent
      link="${prefix}suj_psm2_L1" />
    <child
      link="${prefix}suj_psm2_L2" />
    <axis
      xyz="0 0 1" />
  </joint>
  <link
    name="${prefix}suj_psm2_L3">
    <inertial>
      <origin
        xyz="0 0.0671937597670209 -0.0457966340632676"
        rpy="0 0 0" />
      <mass
        value="0.955411449199707" />
      <inertia
        ixx="0.00502239974642487"
        ixy="0"
        ixz="0"
        iyy="0.00485366592677737"
        iyz="0.000256157144769027"
        izz="0.00220603249495337" />
    </inertial>
    <visual>
      <origin
        xyz="0 0 0"
        rpy="0 0 0" />
      <geometry>
        <mesh
          filename="package://dvrk_description/suj/meshes/suj_psm2_L3.STL" />
      </geometry>
      <material
        name="">
        <color
          rgba="0.792156862745098 0.819607843137255 0.933333333333333 1" />
      </material>
    </visual>
    <collision>
      <origin
        xyz="0 0 0"
        rpy="0 0 0" />
      <geometry>
        <mesh
          filename="package://dvrk_description/suj/meshes/suj_psm2_L3.STL" />
      </geometry>
    </collision>
  </link>
  <joint
    name="${prefix}suj_psm2_J3"
    type="continuous">
    <origin
      xyz="0.4318 0 0"
      rpy="-1.5707963267949 0 -1.5707963267949" />
    <parent
      link="${prefix}suj_psm2_L2" />
    <child
      link="${prefix}suj_psm2_L3" />
    <axis
      xyz="0 -1 0" />
  </joint>
  <link
    name="${prefix}suj_psm2_L4">
    <inertial>
      <origin
        xyz="0 0.13368960726033 0.106531287729481"
        rpy="0 0 0" />
      <mass
        value="3.17073043883153" />
      <inertia
        ixx="0.081480486654553"
        ixy="0"
        ixz="0"
        iyy="0.0179293368302569"
        iyz="-0.0218807182526152"
        izz="0.0668098507562024" />
    </inertial>
    <visual>
      <origin
        xyz="0 0 0"
        rpy="0 0 0" />
      <geometry>
        <mesh
          filename="package://dvrk_description/suj/meshes/suj_psm2_L4.STL" />
      </geometry>
      <material
        name="">
        <color
          rgba="0.792156862745098 0.819607843137255 0.933333333333333 1" />
      </material>
    </visual>
    <collision>
      <origin
        xyz="0 0 0"
        rpy="0 0 0" />
      <geometry>
        <mesh
          filename="package://dvrk_description/suj/meshes/suj_psm2_L4.STL" />
      </geometry>
    </collision>
  </link>
  <joint
    name="${prefix}suj_psm2_J4"
    type="continuous">
    <origin
      xyz="0 0.0730499999999998 0.0609999999999997"
      rpy="1.5707963267949 0 3.14159265358979" />
    <parent
      link="${prefix}suj_psm2_L3" />
    <child
      link="${prefix}suj_psm2_L4" />
    <axis
      xyz="0 1 0" />
  </joint>
  <link
    name="${prefix}suj_ecm_L0">
    <inertial>
      <origin
        xyz="0.0568399826690054 0 0.148466700879736"
        rpy="0 0 0" />
      <mass
        value="8.19045158700106" />
      <inertia
        ixx="0.0849399138017188"
        ixy="0"
        ixz="-0.00950408519583733"
        iyy="0.0840388037894653"
        iyz="0"
        izz="0.0337578517914834" />
    </inertial>
    <visual>
      <origin
        xyz="0 0 0"
        rpy="0 0 0" />
      <geometry>
        <mesh
          filename="package://dvrk_description/suj/meshes/suj_ecm_L0.STL" />
      </geometry>
      <material
        name="">
        <color
          rgba="0.792156862745098 0.819607843137255 0.933333333333333 1" />
      </material>
    </visual>
    <collision>
      <origin
        xyz="0 0 0"
        rpy="0 0 0" />
      <geometry>
        <mesh
          filename="package://dvrk_description/suj/meshes/suj_ecm_L0.STL" />
      </geometry>
    </collision>
  </link>
  <joint
    name="${prefix}suj_ecm_J0"
    type="prismatic">
    <origin
      xyz="0 0.0896 0.7611"
      rpy="3.14159265358979 0 -1.5707963267949" />
    <parent
      link="${prefix}base_link" />
    <child
      link="${prefix}suj_ecm_L0" />
    <axis
      xyz="0 0 -1" />
  <limit
      lower="-0.3798"
      upper="0.8425"
      effort="50"
      velocity="50" />
  </joint>
  <link
    name="${prefix}suj_ecm_L1">
    <inertial>
      <origin
        xyz="0 -0.181423473764043 0.108873680906329"
        rpy="0 0 0" />
      <mass
        value="4.28515446843305" />
      <inertia
        ixx="0.165298975805323"
        ixy="0"
        ixz="0"
        iyy="0.0318879130435779"
        iyz="-0.0216382058279063"
        izz="0.151812373014209" />
    </inertial>
    <visual>
      <origin
        xyz="0 0 0"
        rpy="0 0 0" />
      <geometry>
        <mesh
          filename="package://dvrk_description/suj/meshes/suj_ecm_L1.STL" />
      </geometry>
      <material
        name="">
        <color
          rgba="0.792156862745098 0.819607843137255 0.933333333333333 1" />
      </material>
    </visual>
    <collision>
      <origin
        xyz="0 0 0"
        rpy="0 0 0" />
      <geometry>
        <mesh
          filename="package://dvrk_description/suj/meshes/suj_ecm_L1.STL" />
      </geometry>
    </collision>
  </link>
  <joint
    name="${prefix}suj_ecm_J1"
    type="continuous">
    <origin
      xyz="0 0 0"
      rpy="3.14159265358979 0 1.5707963267949" />
    <parent
      link="${prefix}suj_ecm_L0" />
    <child
      link="${prefix}suj_ecm_L1" />
    <axis
      xyz="0 0 1" />
  </joint>
  <link
    name="${prefix}suj_ecm_L2">
    <inertial>
      <origin
        xyz="0.208919873467034 0 -0.0907666144838897"
        rpy="0 0 0" />
      <mass
        value="3.37391295638731" />
      <inertia
        ixx="0.0170495937307872"
        ixy="0"
        ixz="-0.00102556476360276"
        iyy="0.122648041664091"
        iyz="0"
        izz="0.114779656818464" />
    </inertial>
    <visual>
      <origin
        xyz="0 0 0"
        rpy="0 0 0" />
      <geometry>
        <mesh
          filename="package://dvrk_description/suj/meshes/suj_ecm_L2.STL" />
      </geometry>
      <material
        name="">
        <color
          rgba="0.792156862745098 0.819607843137255 0.933333333333333 1" />
      </material>
    </visual>
    <collision>
      <origin
        xyz="0 0 0"
        rpy="0 0 0" />
      <geometry>
        <mesh
          filename="package://dvrk_description/suj/meshes/suj_ecm_L2.STL" />
      </geometry>
    </collision>
  </link>
  <joint
    name="${prefix}suj_ecm_J2"
    type="continuous">
    <origin
      xyz="0 -0.4318 0.17125"
      rpy="3.14159265358979 0 -1.5707963267949" />
    <parent
      link="${prefix}suj_ecm_L1" />
    <child
      link="${prefix}suj_ecm_L2" />
    <axis
      xyz="0 0 -1" />
  </joint>
  <link
    name="${prefix}suj_ecm_L3">
    <inertial>
      <origin
        xyz="0.101750929950522 0.0259124054818911 0"
        rpy="0 0 0" />
      <mass
        value="3.45916152951232" />
      <inertia
        ixx="0.0229632930111855"
        ixy="-0.00595610077478554"
        ixz="0"
        iyy="0.0229722469896469"
        iyz="0"
        izz="0.0422114398260218" />
    </inertial>
    <visual>
      <origin
        xyz="0 0 0"
        rpy="0 0 0" />
      <geometry>
        <mesh
          filename="package://dvrk_description/suj/meshes/suj_ecm_L3.STL" />
      </geometry>
      <material
        name="">
        <color
          rgba="0.792156862745098 0.819607843137255 0.933333333333333 1" />
      </material>
    </visual>
    <collision>
      <origin
        xyz="0 0 0"
        rpy="0 0 0" />
      <geometry>
        <mesh
          filename="package://dvrk_description/suj/meshes/suj_ecm_L3.STL" />
      </geometry>
    </collision>
  </link>
  <joint
    name="${prefix}suj_ecm_J3"
    type="continuous">
    <origin
      xyz="0.4318 0 0.052"
      rpy="1.5707963267949 0 3.14159265358979" />
    <parent
      link="${prefix}suj_ecm_L2" />
    <child
      link="${prefix}suj_ecm_L3" />
    <axis
      xyz="0 -1 0" />
  </joint>
  <link
    name="${prefix}suj_psm1_L0">
    <inertial>
      <origin
        xyz="0.056839982669005 0 0.148466700879737"
        rpy="0 0 0" />
      <mass
        value="8.19045158700109" />
      <inertia
        ixx="0.0849399138017188"
        ixy="0"
        ixz="-0.00950408519583709"
        iyy="0.0840388037894655"
        iyz="0"
        izz="0.0337578517914837" />
    </inertial>
    <visual>
      <origin
        xyz="0 0 0"
        rpy="0 0 0" />
      <geometry>
        <mesh
          filename="package://dvrk_description/suj/meshes/suj_psm1_L0.STL" />
      </geometry>
      <material
        name="">
        <color
          rgba="0.792156862745098 0.819607843137255 0.933333333333333 1" />
      </material>
    </visual>
    <collision>
      <origin
        xyz="0 0 0"
        rpy="0 0 0" />
      <geometry>
        <mesh
          filename="package://dvrk_description/suj/meshes/suj_psm1_L0.STL" />
      </geometry>
    </collision>
  </link>
  <joint
    name="${prefix}suj_psm1_J0"
    type="prismatic">
    <origin
      xyz="-0.191199999999999 -0.1016 0.761099999999999"
      rpy="3.14159265358979 0 0" />
    <parent
      link="${prefix}base_link" />
    <child
      link="${prefix}suj_psm1_L0" />
    <axis
      xyz="0 0 -1" />
  <limit
      lower="-0.3798"
      upper="0.8425"
      effort="50"
      velocity="50" />
  </joint>
  <link
    name="${prefix}suj_psm1_L1">
    <inertial>
      <origin
        xyz="0 0.181423473764042 -0.108873680906329"
        rpy="0 0 0" />
      <mass
        value="4.28515446843304" />
      <inertia
        ixx="0.165298975805321"
        ixy="0"
        ixz="0"
        iyy="0.0318879130435778"
        iyz="-0.0216382058279061"
        izz="0.151812373014208" />
    </inertial>
    <visual>
      <origin
        xyz="0 0 0"
        rpy="0 0 0" />
      <geometry>
        <mesh
          filename="package://dvrk_description/suj/meshes/suj_psm1_L1.STL" />
      </geometry>
      <material
        name="">
        <color
          rgba="0.792156862745098 0.819607843137255 0.933333333333333 1" />
      </material>
    </visual>
    <collision>
      <origin
        xyz="0 0 0"
        rpy="0 0 0" />
      <geometry>
        <mesh
          filename="package://dvrk_description/suj/meshes/suj_psm1_L1.STL" />
      </geometry>
    </collision>
  </link>
  <joint
    name="${prefix}suj_psm1_J1"
    type="continuous">
    <origin
      xyz="0 0 0"
      rpy="0 0 1.5707963267949" />
    <parent
      link="${prefix}suj_psm1_L0" />
    <child
      link="${prefix}suj_psm1_L1" />
    <axis
      xyz="0 0 -1" />
  </joint>
  <link
    name="${prefix}suj_psm1_L2">
    <inertial>
      <origin
        xyz="0.208919873467034 0 0.0907666144838897"
        rpy="0 0 0" />
      <mass
        value="3.37391295638733" />
      <inertia
        ixx="0.0170495937307872"
        ixy="0"
        ixz="0.00102556476360271"
        iyy="0.122648041664091"
        iyz="0"
        izz="0.114779656818464" />
    </inertial>
    <visual>
      <origin
        xyz="0 0 0"
        rpy="0 0 0" />
      <geometry>
        <mesh
          filename="package://dvrk_description/suj/meshes/suj_psm1_L2.STL" />
      </geometry>
      <material
        name="">
        <color
          rgba="0.792156862745098 0.819607843137255 0.933333333333333 1" />
      </material>
    </visual>
    <collision>
      <origin
        xyz="0 0 0"
        rpy="0 0 0" />
      <geometry>
        <mesh
          filename="package://dvrk_description/suj/meshes/suj_psm1_L2.STL" />
      </geometry>
    </collision>
  </link>
  <joint
    name="${prefix}suj_psm1_J2"
    type="continuous">
    <origin
      xyz="0 0.4318 -0.171250000000001"
      rpy="3.14159265358979 0 1.5707963267949" />
    <parent
      link="${prefix}suj_psm1_L1" />
    <child
      link="${prefix}suj_psm1_L2" />
    <axis
      xyz="0 0 1" />
  </joint>
  <link
    name="${prefix}suj_psm1_L3">
    <inertial>
      <origin
        xyz="0 -0.0671937597670209 0.0457966340632671"
        rpy="0 0 0" />
      <mass
        value="0.955411449199707" />
      <inertia
        ixx="0.00502239974642493"
        ixy="0"
        ixz="0"
        iyy="0.0048536659267774"
        iyz="0.000256157144769039"
        izz="0.00220603249495337" />
    </inertial>
    <visual>
      <origin
        xyz="0 0 0"
        rpy="0 0 0" />
      <geometry>
        <mesh
          filename="package://dvrk_description/suj/meshes/suj_psm1_L3.STL" />
      </geometry>
      <material
        name="">
        <color
          rgba="0.792156862745098 0.819607843137255 0.933333333333333 1" />
      </material>
    </visual>
    <collision>
      <origin
        xyz="0 0 0"
        rpy="0 0 0" />
      <geometry>
        <mesh
          filename="package://dvrk_description/suj/meshes/suj_psm1_L3.STL" />
      </geometry>
    </collision>
  </link>
  <joint
    name="${prefix}suj_psm1_J3"
    type="continuous">
    <origin
      xyz="0.4318 0 0"
      rpy="1.5707963267949 0 -1.5707963267949" />
    <parent
      link="${prefix}suj_psm1_L2" />
    <child
      link="${prefix}suj_psm1_L3" />
    <axis
      xyz="0 1 0" />
  </joint>
  <link
    name="${prefix}suj_psm1_L4">
    <inertial>
      <origin
        xyz="0 0.13368960726033 0.106531287729481"
        rpy="0 0 0" />
      <mass
        value="3.17073043883155" />
      <inertia
        ixx="0.0814804866545533"
        ixy="0"
        ixz="0"
        iyy="0.0179293368302569"
        iyz="-0.0218807182526152"
        izz="0.0668098507562027" />
    </inertial>
    <visual>
      <origin
        xyz="0 0 0"
        rpy="0 0 0" />
      <geometry>
        <mesh
          filename="package://dvrk_description/suj/meshes/suj_psm1_L4.STL" />
      </geometry>
      <material
        name="">
        <color
          rgba="0.792156862745098 0.819607843137255 0.933333333333333 1" />
      </material>
    </visual>
    <collision>
      <origin
        xyz="0 0 0"
        rpy="0 0 0" />
      <geometry>
        <mesh
          filename="package://dvrk_description/suj/meshes/suj_psm1_L4.STL" />
      </geometry>
    </collision>
  </link>
  <joint
    name="${prefix}suj_psm1_J4"
    type="continuous">
    <origin
      xyz="0 -0.0730499999999998 -0.0609999999999999"
      rpy="-1.5707963267949 0 3.14159265358979" />
    <parent
      link="${prefix}suj_psm1_L3" />
    <child
      link="${prefix}suj_psm1_L4" />
    <axis
      xyz="0 1 0" />
  </joint>
  <link
    name="${prefix}suj_psm3_L0">
    <inertial>
      <origin
        xyz="0.0602109648274594 0 0.113199880625867"
        rpy="0 0 0" />
      <mass
        value="6.04817279598793" />
      <inertia
        ixx="0.042751844253079"
        ixy="0"
        ixz="-0.00566678005551946"
        iyy="0.0405000183180794"
        iyz="0"
        izz="0.023227300149106" />
    </inertial>
    <visual>
      <origin
        xyz="0 0 0"
        rpy="0 0 0" />
      <geometry>
        <mesh
          filename="package://dvrk_description/suj/meshes/suj_psm3_L0.STL" />
      </geometry>
      <material
        name="">
        <color
          rgba="0.792156862745098 0.819607843137255 0.933333333333333 1" />
      </material>
    </visual>
    <collision>
      <origin
        xyz="0 0 0"
        rpy="0 0 0" />
      <geometry>
        <mesh
          filename="package://dvrk_description/suj/meshes/suj_psm3_L0.STL" />
      </geometry>
    </collision>
  </link>
  <joint
    name="${prefix}suj_psm3_J0"
    type="prismatic">
    <origin
      xyz="0 0.0895999999999999 0.3813"
      rpy="3.14159265358979 0 -1.5707963267949" />
    <parent
      link="${prefix}base_link" />
    <child
      link="${prefix}suj_psm3_L0" />
    <axis
      xyz="0 0 -1" />
  <limit
      lower="0"
      upper="1.2223"
      effort="50"
      velocity="50" />
  </joint>
  <link
    name="${prefix}suj_psm3_L1">
    <inertial>
      <origin
        xyz="0 -0.269226910798469 0.0974465195036079"
        rpy="0 0 0" />
      <mass
        value="9.2143433650029" />
      <inertia
        ixx="0.512543337774863"
        ixy="0"
        ixz="0"
        iyy="0.046675533244729"
        iyz="-0.022324667193201"
        izz="0.500775909008121" />
    </inertial>
    <visual>
      <origin
        xyz="0 0 0"
        rpy="0 0 0" />
      <geometry>
        <mesh
          filename="package://dvrk_description/suj/meshes/suj_psm3_L1.STL" />
      </geometry>
      <material
        name="">
        <color
          rgba="0.792156862745098 0.819607843137255 0.933333333333333 1" />
      </material>
    </visual>
    <collision>
      <origin
        xyz="0 0 0"
        rpy="0 0 0" />
      <geometry>
        <mesh
          filename="package://dvrk_description/suj/meshes/suj_psm3_L1.STL" />
      </geometry>
    </collision>
  </link>
  <joint
    name="${prefix}suj_psm3_J1"
    type="continuous">
    <origin
      xyz="0 0 0"
      rpy="3.14159265358979 0 1.5707963267949" />
    <parent
      link="${prefix}suj_psm3_L0" />
    <child
      link="${prefix}suj_psm3_L1" />
    <axis
      xyz="0 0 1" />
  </joint>
  <link
    name="${prefix}suj_psm3_L2">
    <inertial>
      <origin
        xyz="0.208919873467035 0 0.0907666144838893"
        rpy="0 0 0" />
      <mass
        value="3.37391295638732" />
      <inertia
        ixx="0.0170495937307872"
        ixy="0"
        ixz="0.00102556476360266"
        iyy="0.122648041664091"
        iyz="0"
        izz="0.114779656818464" />
    </inertial>
    <visual>
      <origin
        xyz="0 0 0"
        rpy="0 0 0" />
      <geometry>
        <mesh
          filename="package://dvrk_description/suj/meshes/suj_psm3_L2.STL" />
      </geometry>
      <material
        name="">
        <color
          rgba="0.792156862745098 0.819607843137255 0.933333333333333 1" />
      </material>
    </visual>
    <collision>
      <origin
        xyz="0 0 0"
        rpy="0 0 0" />
      <geometry>
        <mesh
          filename="package://dvrk_description/suj/meshes/suj_psm3_L2.STL" />
      </geometry>
    </collision>
  </link>
  <joint
    name="${prefix}suj_psm3_J2"
    type="continuous">
    <origin
      xyz="0 -0.5842 -0.000249999999999639"
      rpy="3.14159265358979 0 -1.5707963267949" />
    <parent
      link="${prefix}suj_psm3_L1" />
    <child
      link="${prefix}suj_psm3_L2" />
    <axis
      xyz="0 0 -1" />
  </joint>
  <link
    name="${prefix}suj_psm3_L3">
    <inertial>
      <origin
        xyz="0 -0.147369605966979 0.0299587011265839"
        rpy="0 0 0" />
      <mass
        value="1.46016558605931" />
      <inertia
        ixx="0.0128891233532759"
        ixy="0"
        ixz="0"
        iyy="0.00658384974944233"
        iyz="0.00230089243299317"
        izz="0.00938095830526967" />
    </inertial>
    <visual>
      <origin
        xyz="0 0 0"
        rpy="0 0 0" />
      <geometry>
        <mesh
          filename="package://dvrk_description/suj/meshes/suj_psm3_L3.STL" />
      </geometry>
      <material
        name="">
        <color
          rgba="0.792156862745098 0.819607843137255 0.933333333333333 1" />
      </material>
    </visual>
    <collision>
      <origin
        xyz="0 0 0"
        rpy="0 0 0" />
      <geometry>
        <mesh
          filename="package://dvrk_description/suj/meshes/suj_psm3_L3.STL" />
      </geometry>
    </collision>
  </link>
  <joint
    name="${prefix}suj_psm3_J3"
    type="continuous">
    <origin
      xyz="0.431800000000001 0 0"
      rpy="1.5707963267949 0 -1.5707963267949" />
    <parent
      link="${prefix}suj_psm3_L2" />
    <child
      link="${prefix}suj_psm3_L3" />
    <axis
      xyz="0 -1 0" />
  </joint>
  <link
    name="${prefix}suj_psm3_L4">
    <inertial>
      <origin
        xyz="0 0.133689607260329 0.106531287729481"
        rpy="0 0 0" />
      <mass
        value="3.17073043883155" />
      <inertia
        ixx="0.0814804866545532"
        ixy="0"
        ixz="0"
        iyy="0.0179293368302569"
        iyz="-0.0218807182526152"
        izz="0.0668098507562025" />
    </inertial>
    <visual>
      <origin
        xyz="0 0 0"
        rpy="0 0 0" />
      <geometry>
        <mesh
          filename="package://dvrk_description/suj/meshes/suj_psm3_L4.STL" />
      </geometry>
      <material
        name="">
        <color
          rgba="0.792156862745098 0.819607843137255 0.933333333333333 1" />
      </material>
    </visual>
    <collision>
      <origin
        xyz="0 0 0"
        rpy="0 0 0" />
      <geometry>
        <mesh
          filename="package://dvrk_description/suj/meshes/suj_psm3_L4.STL" />
      </geometry>
    </collision>
  </link>
  <joint
    name="${prefix}suj_psm3_J4"
    type="continuous">
    <origin
      xyz="0 -0.199949999999999 -0.061"
      rpy="-1.5707963267949 0 0" />
    <parent
      link="${prefix}suj_psm3_L3" />
    <child
      link="${prefix}suj_psm3_L4" />
    <axis
      xyz="0 1 0" />
  </joint>
<!-- //////////////////////////////////////////////////////////////////////////// -->

  </xacro:macro>

</robot>
