<robot
  name="PSM">
  <link
    name="base_link">
    <inertial>
      <origin
        xyz="-1.2188E-08 -0.17016 -0.085607"
        rpy="0 0 0" />
      <mass
        value="2.0161" />
      <inertia
        ixx="0"
        ixy="0"
        ixz="0"
        iyy="0"
        iyz="0"
        izz="0" />
    </inertial>
    <visual>
      <origin
        xyz="0 0 0"
        rpy="0 0 0" />
      <geometry>
        <mesh
          filename="package://dvrk_model/PSM/meshes/base_link.STL" />
      </geometry>
      <material
        name="">
        <color
          rgba="0.89804 0.91765 0.92941 1" />
      </material>
    </visual>
    <collision>
      <origin
        xyz="0 0 0"
        rpy="0 0 0" />
      <geometry>
        <mesh
          filename="package://dvrk_model/PSM/meshes/base_link.STL" />
      </geometry>
    </collision>
  </link>
  <link
    name="yaw_Link">
    <inertial>
      <origin
        xyz="-0.038769 7.8481E-05 0.041596"
        rpy="0 0 0" />
      <mass
        value="1.4705" />
      <inertia
        ixx="0"
        ixy="0"
        ixz="0"
        iyy="0"
        iyz="0"
        izz="0" />
    </inertial>
    <visual>
      <origin
        xyz="0 0 0"
        rpy="0 0 0" />
      <geometry>
        <mesh
          filename="package://dvrk_model/PSM/meshes/yaw_Link.STL" />
      </geometry>
      <material
        name="">
        <color
          rgba="0.89804 0.91765 0.92941 1" />
      </material>
    </visual>
    <collision>
      <origin
        xyz="0 0 0"
        rpy="0 0 0" />
      <geometry>
        <mesh
          filename="package://dvrk_model/PSM/meshes/yaw_Link.STL" />
      </geometry>
    </collision>
  </link>
  <joint
    name="yaw_joint"
    type="revolute">
    <origin
      xyz="0 0 0"
      rpy="1.57079632679489 -1.5707963267949 0" />
    <parent
      link="base_link" />
    <child
      link="yaw_Link" />
    <axis
      xyz="0 0 -1" />
    <limit
      lower="-1.605"
      upper="1.5994"
      effort="1000"
      velocity="10" />
  </joint>
  <link
    name="pitch_back_Link">
    <inertial>
      <origin
        xyz="-0.012175 -0.036897 3.5213E-05"
        rpy="0 0 0" />
      <mass
        value="0.99511" />
      <inertia
        ixx="0"
        ixy="0"
        ixz="0"
        iyy="0"
        iyz="0"
        izz="0" />
    </inertial>
    <visual>
      <origin
        xyz="0 0 0"
        rpy="0 0 0" />
      <geometry>
        <mesh
          filename="package://dvrk_model/PSM/meshes/pitch_back_Link.STL" />
      </geometry>
      <material
        name="">
        <color
          rgba="0.89804 0.91765 0.92941 1" />
      </material>
    </visual>
    <collision>
      <origin
        xyz="0 0 0"
        rpy="0 0 0" />
      <geometry>
        <mesh
          filename="package://dvrk_model/PSM/meshes/pitch_back_Link.STL" />
      </geometry>
    </collision>
  </link>
  <joint
    name="pitch_back_joint"
    type="revolute">
    <origin
      xyz="0 0 0.0295999999999997"
      rpy="-1.5707963267949 -0.290727597908961 1.77865254633244E-15" />
    <parent
      link="yaw_Link" />
    <child
      link="pitch_back_Link" />
    <axis
      xyz="0 0 1" />
    <limit
      lower="-0.93556"
      upper="0.94249"
      effort="1000"
      velocity="10" />
  </joint>
  <link
    name="pitch_bottom_Link">
    <inertial>
      <origin
        xyz="0.25683 -0.010348 -6.1792E-06"
        rpy="0 0 0" />
      <mass
        value="0.44569" />
      <inertia
        ixx="0"
        ixy="0"
        ixz="0"
        iyy="0"
        iyz="0"
        izz="0" />
    </inertial>
    <visual>
      <origin
        xyz="0 0 0"
        rpy="0 0 0" />
      <geometry>
        <mesh
          filename="package://dvrk_model/PSM/meshes/pitch_bottom_Link.STL" />
      </geometry>
      <material
        name="">
        <color
          rgba="0.89804 0.91765 0.92941 1" />
      </material>
    </visual>
    <collision>
      <origin
        xyz="0 0 0"
        rpy="0 0 0" />
      <geometry>
        <mesh
          filename="package://dvrk_model/PSM/meshes/pitch_bottom_Link.STL" />
      </geometry>
    </collision>
  </link>
  <joint
    name="pitch_bottom_joint"
    type="revolute">
    <origin
      xyz="0.15 0 0"
      rpy="0 0 1.8615" />
    <parent
      link="pitch_back_Link" />
    <child
      link="pitch_bottom_Link" />
    <axis
      xyz="0 0 1" />
    <limit
      lower="-0.94249"
      upper="0.93556"
      effort="1000"
      velocity="10" />
  </joint>
  <link
    name="pitch_end_Link">
    <inertial>
      <origin
        xyz="-0.0019293 -0.13613 -5.9704E-08"
        rpy="0 0 0" />
      <mass
        value="2.091" />
      <inertia
        ixx="0"
        ixy="0"
        ixz="0"
        iyy="0"
        iyz="0"
        izz="0" />
    </inertial>
    <visual>
      <origin
        xyz="0 0 0"
        rpy="0 0 0" />
      <geometry>
        <mesh
          filename="package://dvrk_model/PSM/meshes/pitch_end_Link.STL" />
      </geometry>
      <material
        name="">
        <color
          rgba="0.89804 0.91765 0.92941 1" />
      </material>
    </visual>
    <collision>
      <origin
        xyz="0 0 0"
        rpy="0 0 0" />
      <geometry>
        <mesh
          filename="package://dvrk_model/PSM/meshes/pitch_end_Link.STL" />
      </geometry>
    </collision>
  </link>
  <joint
    name="pitch_end_joint"
    type="revolute">
    <origin
      xyz="0.516 0 0"
      rpy="0 0 -3.5146E-13" />
    <parent
      link="pitch_bottom_Link" />
    <child
      link="pitch_end_Link" />
    <axis
      xyz="0 0 1" />
    <limit
      lower="-0.93556"
      upper="0.94249"
      effort="1000"
      velocity="10" />
  </joint>
  <link
    name="main_insertion_Link">
    <inertial>
      <origin
        xyz="0.0040563 -0.00010934 0.010292"
        rpy="0 0 0" />
      <mass
        value="0.22491" />
      <inertia
        ixx="1.7667E-05"
        ixy="-6.2173E-08"
        ixz="1.2562E-05"
        iyy="2.6598E-05"
        iyz="8.744E-08"
        izz="8.9322E-06" />
    </inertial>
    <visual>
      <origin
        xyz="0 0 0"
        rpy="0 0 0" />
      <geometry>
        <mesh
          filename="package://dvrk_model/PSM/meshes/main_insertion_Link.STL" />
      </geometry>
      <material
        name="">
        <color
          rgba="1 0.55686 0.058824 0.4" />
      </material>
    </visual>
    <collision>
      <origin
        xyz="0 0 0"
        rpy="0 0 0" />
      <geometry>
        <mesh
          filename="package://dvrk_model/PSM/meshes/main_insertion_Link.STL" />
      </geometry>
    </collision>
  </link>
  <joint
    name="main_insertion_joint"
    type="prismatic">
    <origin
      xyz="0.0430000000019171 -0.288089999999913 0"
      rpy="1.5707963267949 0 3.14159265358979" />
    <parent
      link="pitch_end_Link" />
    <child
      link="main_insertion_Link" />
    <axis
      xyz="0 0 -1" />
    <limit
      lower="0"
      upper="0.24"
      effort="1000"
      velocity="1" />
  </joint>
  <link
    name="tool_roll_link">
    <inertial>
      <origin
        xyz="-1.1311E-08 -7.4559E-09 -0.0058234"
        rpy="0 0 0" />
      <mass
        value="0.00033225" />
      <inertia
        ixx="0"
        ixy="0"
        ixz="0"
        iyy="0"
        iyz="0"
        izz="0" />
    </inertial>
    <visual>
      <origin
        xyz="0 0 0"
        rpy="0 0 0" />
      <geometry>
        <mesh
          filename="package://dvrk_model/PSM/meshes/tool_roll_link.STL" />
      </geometry>
      <material
        name="">
        <color
          rgba="0.79608 0.82353 0.93725 1" />
      </material>
    </visual>
    <collision>
      <origin
        xyz="0 0 0"
        rpy="0 0 0" />
      <geometry>
        <mesh
          filename="package://dvrk_model/PSM/meshes/tool_roll_link.STL" />
      </geometry>
    </collision>
  </link>
  <joint
    name="tool_roll_joint"
    type="revolute">
    <origin
      xyz="0 0 0.416199999999902"
      rpy="0 0 3.14159265358979" />
    <parent
      link="main_insertion_Link" />
    <child
      link="tool_roll_link" />
    <axis
      xyz="0 0 -1" />
    <limit
      lower="-3.14159"
      upper="3.14159"
      effort="1000"
      velocity="10" />
  </joint>
  <link
    name="tool_pitch_link">
    <inertial>
      <origin
        xyz="0.0035766 -4.8675E-05 4.4413E-06"
        rpy="0 0 0" />
      <mass
        value="0.00025977" />
      <inertia
        ixx="1.4998E-13"
        ixy="1.9324E-12"
        ixz="4.1907E-12"
        iyy="1.4212E-10"
        iyz="-5.7032E-14"
        izz="1.4202E-10" />
    </inertial>
    <visual>
      <origin
        xyz="0 0 0"
        rpy="0 0 0" />
      <geometry>
        <mesh
          filename="package://dvrk_model/PSM/meshes/tool_pitch_link.STL" />
      </geometry>
      <material
        name="">
        <color
          rgba="0.79608 0.82353 0.93725 1" />
      </material>
    </visual>
    <collision>
      <origin
        xyz="0 0 0"
        rpy="0 0 0" />
      <geometry>
        <mesh
          filename="package://dvrk_model/PSM/meshes/tool_pitch_link.STL" />
      </geometry>
    </collision>
  </link>
  <joint
    name="tool_pitch_joint"
    type="revolute">
    <origin
      xyz="0 0 0"
      rpy="1.5707963267949 -1.5707963267949 0" />
    <parent
      link="tool_roll_link" />
    <child
      link="tool_pitch_link" />
    <axis
      xyz="0 0 -1" />
    <limit
      lower="-1.5708"
      upper="1.5708"
      effort="1000"
      velocity="10" />
  </joint>
  <link
    name="tool_yaw_link">
    <inertial>
      <origin
        xyz="-8.7349E-16 6.7391E-14 -5E-05"
        rpy="0 0 0" />
      <mass
        value="6.6366E-06" />
      <inertia
        ixx="0"
        ixy="0"
        ixz="0"
        iyy="0"
        iyz="0"
        izz="0" />
    </inertial>
    <visual>
      <origin
        xyz="0 0 0"
        rpy="0 0 0" />
      <geometry>
        <mesh
          filename="package://dvrk_model/PSM/meshes/tool_yaw_link.STL" />
      </geometry>
      <material
        name="">
        <color
          rgba="0.79608 0.82353 0.93725 1" />
      </material>
    </visual>
    <collision>
      <origin
        xyz="0 0 0"
        rpy="0 0 0" />
      <geometry>
        <mesh
          filename="package://dvrk_model/PSM/meshes/tool_yaw_link.STL" />
      </geometry>
    </collision>
  </link>
  <joint
    name="tool_yaw_joint"
    type="revolute">
    <origin
      xyz="0.00910000000003011 -5.00000000686063E-05 0"
      rpy="1.57079632679486 -1.5707963267949 0" />
    <parent
      link="tool_pitch_link" />
    <child
      link="tool_yaw_link" />
    <axis
      xyz="0 0 1" />
    <limit
      lower="-1.5708"
      upper="1.5708"
      effort="1000"
      velocity="10" />
  </joint>
  <link
    name="tool_gripper1_link">
    <inertial>
      <origin
        xyz="0.00018874 0.0013526 -0.00091695"
        rpy="0 0 0" />
      <mass
        value="3.907E-05" />
      <inertia
        ixx="0"
        ixy="0"
        ixz="0"
        iyy="0"
        iyz="0"
        izz="0" />
    </inertial>
    <visual>
      <origin
        xyz="0 0 0"
        rpy="0 0 0" />
      <geometry>
        <mesh
          filename="package://dvrk_model/PSM/meshes/tool_gripper1_link.STL" />
      </geometry>
      <material
        name="">
        <color
          rgba="0.79608 0.82353 0.93725 1" />
      </material>
    </visual>
    <collision>
      <origin
        xyz="0 0 0"
        rpy="0 0 0" />
      <geometry>
        <mesh
          filename="package://dvrk_model/PSM/meshes/tool_gripper1_link.STL" />
      </geometry>
    </collision>
  </link>
  <joint
    name="tool_gripper1_joint"
    type="revolute">
    <origin
      xyz="0 0 0"
      rpy="0 0 1.7432292974031E-33" />
    <parent
      link="tool_yaw_link" />
    <child
      link="tool_gripper1_link" />
    <axis
      xyz="0 0 1" />
    <limit
      lower="0"
      upper="1"
      effort="0"
      velocity="0" />
  </joint>
  <link
    name="tool_gripper2_link">
    <inertial>
      <origin
        xyz="-0.00018874 0.0013526 0.00090695"
        rpy="0 0 0" />
      <mass
        value="3.907E-05" />
      <inertia
        ixx="0"
        ixy="0"
        ixz="0"
        iyy="0"
        iyz="0"
        izz="0" />
    </inertial>
    <visual>
      <origin
        xyz="0 0 0"
        rpy="0 0 0" />
      <geometry>
        <mesh
          filename="package://dvrk_model/PSM/meshes/tool_gripper2_link.STL" />
      </geometry>
      <material
        name="">
        <color
          rgba="0.79608 0.82353 0.93725 1" />
      </material>
    </visual>
    <collision>
      <origin
        xyz="0 0 0"
        rpy="0 0 0" />
      <geometry>
        <mesh
          filename="package://dvrk_model/PSM/meshes/tool_gripper2_link.STL" />
      </geometry>
    </collision>
  </link>
  <joint
    name="tool_gripper2_joint"
    type="revolute">
    <origin
      xyz="0 0 0"
      rpy="0 0 1.7432292974031E-33" />
    <parent
      link="tool_yaw_link" />
    <child
      link="tool_gripper2_link" />
    <axis
      xyz="0 0 1" />
    <limit
      lower="0"
      upper="1"
      effort="0"
      velocity="0" />
  </joint>
  <link
    name="pitch_top_Link">
    <inertial>
      <origin
        xyz="0.31246 -0.00056566 -3.4131E-07"
        rpy="0 0 0" />
      <mass
        value="0.17841" />
      <inertia
        ixx="0"
        ixy="0"
        ixz="0"
        iyy="0"
        iyz="0"
        izz="0" />
    </inertial>
    <visual>
      <origin
        xyz="0 0 0"
        rpy="0 0 0" />
      <geometry>
        <mesh
          filename="package://dvrk_model/PSM/meshes/pitch_top_Link.STL" />
      </geometry>
      <material
        name="">
        <color
          rgba="0.89804 0.91765 0.92941 1" />
      </material>
    </visual>
    <collision>
      <origin
        xyz="0 0 0"
        rpy="0 0 0" />
      <geometry>
        <mesh
          filename="package://dvrk_model/PSM/meshes/pitch_top_Link.STL" />
      </geometry>
    </collision>
  </link>
  <joint
    name="pitch_top_joint"
    type="revolute">
    <origin
      xyz="0.183657966666658 0.0141205977162999 0"
      rpy="0 0 1.86152392470386" />
    <parent
      link="pitch_back_Link" />
    <child
      link="pitch_top_Link" />
    <axis
      xyz="0 0 1" />
    <limit
      lower="-0.94249"
      upper="0.93556"
      effort="1000"
      velocity="10" />
  </joint>
  <link
    name="pitch_front_Link">
    <inertial>
      <origin
        xyz="0.096269 2.3259E-14 0.047551"
        rpy="0 0 0" />
      <mass
        value="0.074425" />
      <inertia
        ixx="0"
        ixy="0"
        ixz="0"
        iyy="0"
        iyz="0"
        izz="0" />
    </inertial>
    <visual>
      <origin
        xyz="0 0 0"
        rpy="0 0 0" />
      <geometry>
        <mesh
          filename="package://dvrk_model/PSM/meshes/pitch_front_Link.STL" />
      </geometry>
      <material
        name="">
        <color
          rgba="0.89804 0.91765 0.92941 1" />
      </material>
    </visual>
    <collision>
      <origin
        xyz="0 0 0"
        rpy="0 0 0" />
      <geometry>
        <mesh
          filename="package://dvrk_model/PSM/meshes/pitch_front_Link.STL" />
      </geometry>
    </collision>
  </link>
  <joint
    name="pitch_front_joint"
    type="revolute">
    <origin
      xyz="0 0 -0.0664000000000003"
      rpy="-1.57079632679489 -0.290727597908941 1.77865254633244E-15" />
    <parent
      link="yaw_Link" />
    <child
      link="pitch_front_Link" />
    <axis
      xyz="0 0 1" />
    <limit
      lower="-0.93556"
      upper="0.94249"
      effort="1000"
      velocity="10" />
  </joint>
</robot>
